Workbook
Name SegmentaciónDeDatos_CLIENTE: #N/A
Name SegmentaciónDeDatos_COLOR: #N/A
Name SegmentaciónDeDatos_Fecha: #N/A

Sheet Codigo 
A1: 0 | E1: Serie documento | G1: Fecha | H1: Cantidad | I1: EXISTENTE | J1: PEDIDO FALTANTE | K1: % | L1: FECHA DE ENTREGA | M1: PRODUCCION | N1: FECHA LOGISTICA
A2: Producto: 2130002716050701 / BISA PLATO LISO 27 BLANCO C/F NEGRO DECORADO | B2: =+MID(A2,13,6) -> 300027 | C2: =_xlfn.CONCAT(+VLOOKUP(VALUE(MID(A2,13,2)),'Tabla de codigos'!$A$2:$B$60,2,1)," ",VLOOKUP(VALUE(MID(A2,15,4)),'Tabla de codigos'!$E$2:$F$102,2,1)) -> PLATO LISO 27 | D2: AEZKOA | E2: VT2 | F2: 00004838 | G2: 02/04/2025 | H2: 357 | I2: 0 | J2: =+H2-I2 -> 357 | K2: =(SUM(I2))/(SUM(H2)) -> 0
A3: Producto: 2111001327010101 / BISA CUBETA 10 NEGRO MOTAS | B3: =+MID(A3,13,6) -> 110013 | C3: =_xlfn.CONCAT(+VLOOKUP(VALUE(MID(A3,13,2)),'Tabla de codigos'!$A$2:$B$60,2,1)," ",VLOOKUP(VALUE(MID(A3,15,4)),'Tabla de codigos'!$E$2:$F$102,2,1)) -> CUBETA 10 | D3: ARGELIA BERENICE CONTRERAS VALDÉS | E3: VT1 | F3: 00003517 | G3: 30/01/2025 | H3: 30 | I3: 1 | J3: =+H3-I3 -> 29 | K3: =(SUM(I3))/(SUM(H3)) -> 0.033333333 | O3: =(H3)/(IF(A3="","-",VLOOKUP(A3,'[1]CATALOGO PZXCAJA'!$A$2:$C$5000,2,0))) -> 2.5
A4: Producto: 2101002516050101 / BISA BACINICA 24 BLANCO C/F NEGRO | B4: =+MID(A4,13,6) -> 010025 | C4: =_xlfn.CONCAT(+VLOOKUP(VALUE(MID(A4,13,2)),'Tabla de codigos'!$A$2:$B$60,2,1)," ",VLOOKUP(VALUE(MID(A4,15,4)),'Tabla de codigos'!$E$2:$F$102,2,1)) -> BACINICA 24 | D4: Casa Valle Chab | E4: VT2 | F4: 00004759 | G4: 15/01/2025 | H4: 36 | I4: 5 | J4: =+H4-I4 -> 31 | K4: =(SUM(I4))/(SUM(H4)) -> 0.13888889 | O4: =(H4)/(IF(A4="","-",VLOOKUP(A4,'[1]CATALOGO PZXCAJA'!$A$2:$C$5000,2,0))) -> 3
A5: Producto: 2142002129010101 / BISA TORTILLERO 18 ROJO | B5: =+MID(A5,13,6) -> 420021 | C5: =_xlfn.CONCAT(+VLOOKUP(VALUE(MID(A5,13,2)),'Tabla de codigos'!$A$2:$B$60,2,1)," ",VLOOKUP(VALUE(MID(A5,15,4)),'Tabla de codigos'!$E$2:$F$102,2,1)) -> TORTILLERO 18 | D5: COCINA MEXICANA | E5: VT1 | F5: 00003523 | G5: 04/02/2025 | H5: 96 | I5: 0 | J5: =+H5-I5 -> 96 | K5: =(SUM(I5))/(SUM(H5)) -> 0
A6: Producto: 2130001702010101 / BISA PLATO LISO 16 A/T | B6: =+MID(A6,13,6) -> 300017 | C6: =_xlfn.CONCAT(+VLOOKUP(VALUE(MID(A6,13,2)),'Tabla de codigos'!$A$2:$B$60,2,1)," ",VLOOKUP(VALUE(MID(A6,15,4)),'Tabla de codigos'!$E$2:$F$102,2,1)) -> PLATO LISO 16 | D6: COMPARTIENDO CON EL CHEF | E6: VT1 | F6: 00003518 | G6: 04/02/2025 | H6: 48 | I6: 3 | J6: =+H6-I6 -> 45 | O6: =(H6)/(IF(A6="","-",VLOOKUP(A6,'[1]CATALOGO PZXCAJA'!$A$2:$C$5000,2,0))) -> 8
A7: Producto: 2130002202010101 / BISA PLATO LISO 20 A/T | B7: =+MID(A7,13,6) -> 300022 | C7: =_xlfn.CONCAT(+VLOOKUP(VALUE(MID(A7,13,2)),'Tabla de codigos'!$A$2:$B$60,2,1)," ",VLOOKUP(VALUE(MID(A7,15,4)),'Tabla de codigos'!$E$2:$F$102,2,1)) -> PLATO LISO 20 | D7: COMPARTIENDO CON EL CHEF | E7: VT1 | F7: 00003518 | G7: 04/02/2025 | H7: 72 | I7: =6+3 -> 9 | J7: =+H7-I7 -> 63 | O7: =(H7)/(IF(A7="","-",VLOOKUP(A7,'[1]CATALOGO PZXCAJA'!$A$2:$C$5000,2,0))) -> 12
A8: Producto: 2130002702010101 / BISA PLATO LISO 27 A/T | B8: =+MID(A8,13,6) -> 300027 | C8: =_xlfn.CONCAT(+VLOOKUP(VALUE(MID(A8,13,2)),'Tabla de codigos'!$A$2:$B$60,2,1)," ",VLOOKUP(VALUE(MID(A8,15,4)),'Tabla de codigos'!$E$2:$F$102,2,1)) -> PLATO LISO 27 | D8: COMPARTIENDO CON EL CHEF | E8: VT1 | F8: 00003518 | G8: 04/02/2025 | H8: 72 | I8: =6+66 -> 72 | J8: =+H8-I8 -> 0 | K8: =(SUM(I6:I8))/(SUM(H6:H8)) -> 0.4375 | O8: =(H8)/(IF(A8="","-",VLOOKUP(A8,'[1]CATALOGO PZXCAJA'!$A$2:$C$5000,2,0))) -> 12
A9: Producto: 1103000919010101 / BISA BAÑO 5 GALVANIZADO | B9: =+MID(A9,13,6) -> 030009 | C9: =_xlfn.CONCAT(+VLOOKUP(VALUE(MID(A9,13,2)),'Tabla de codigos'!$A$2:$B$60,2,1)," ",VLOOKUP(VALUE(MID(A9,15,4)),'Tabla de codigos'!$E$2:$F$102,2,1)) -> BAÑO 5 | D9: ERENDIRA MARLENE GOMEZ RIVAS | E9: BO | F9: 00000749 | G9: 08/10/2024 | H9: 40 | I9: 0 | J9: =+H9-I9 -> 40 | O9: =(H9)/(IF(A9="","-",VLOOKUP(A9,'[1]CATALOGO PZXCAJA'!$A$2:$C$5000,2,0))) -> #N/A
A10: Producto: 1103001019010101 / BISA BAÑO 6 GALVANIZADO | B10: =+MID(A10,13,6) -> 030010 | C10: =_xlfn.CONCAT(+VLOOKUP(VALUE(MID(A10,13,2)),'Tabla de codigos'!$A$2:$B$60,2,1)," ",VLOOKUP(VALUE(MID(A10,15,4)),'Tabla de codigos'!$E$2:$F$102,2,1)) -> BAÑO 6 | D10: ERENDIRA MARLENE GOMEZ RIVAS | E10: BO | F10: 00000749 | G10: 08/10/2024 | H10: 14 | I10: 0 | J10: =+H10-I10 -> 14 | K10: =(SUM(I9:I10))/(SUM(H9:H10)) -> 0 | O10: =(H10)/(IF(A10="","-",VLOOKUP(A10,'[1]CATALOGO PZXCAJA'!$A$2:$C$5000,2,0))) -> #N/A
A11: Producto: 2106003302010101 / BISA BUDINERA 42 A/T | B11: =+MID(A11,13,6) -> 060033 | C11: =_xlfn.CONCAT(+VLOOKUP(VALUE(MID(A11,13,2)),'Tabla de codigos'!$A$2:$B$60,2,1)," ",VLOOKUP(VALUE(MID(A11,15,4)),'Tabla de codigos'!$E$2:$F$102,2,1)) -> BUDINERA 42 | D11: ERENDIRA MARLENE GOMEZ RIVAS | E11: BO | F11: 00000757 | G11: 08/10/2024 | H11: 12 | I11: 0 | J11: =+H11-I11 -> 12 | O11: =(H11)/(IF(A11="","-",VLOOKUP(A11,'[1]CATALOGO PZXCAJA'!$A$2:$C$5000,2,0))) -> 6
A12: Producto: 2111001227010101 / BISA CUBETA 8 NEGRO MOTAS | B12: =+MID(A12,13,6) -> 110012 | C12: =_xlfn.CONCAT(+VLOOKUP(VALUE(MID(A12,13,2)),'Tabla de codigos'!$A$2:$B$60,2,1)," ",VLOOKUP(VALUE(MID(A12,15,4)),'Tabla de codigos'!$E$2:$F$102,2,1)) -> CUBETA 8 | D12: ERENDIRA MARLENE GOMEZ RIVAS | E12: BO | F12: 00000757 | G12: 08/10/2024 | H12: 24 | I12: 24 | J12: =+H12-I12 -> 0 | O12: =(H12)/(IF(A12="","-",VLOOKUP(A12,'[1]CATALOGO PZXCAJA'!$A$2:$C$5000,2,0))) -> 2
A13: Producto: 2111001327010101 / BISA CUBETA 10 NEGRO MOTAS | B13: =+MID(A13,13,6) -> 110013 | C13: =_xlfn.CONCAT(+VLOOKUP(VALUE(MID(A13,13,2)),'Tabla de codigos'!$A$2:$B$60,2,1)," ",VLOOKUP(VALUE(MID(A13,15,4)),'Tabla de codigos'!$E$2:$F$102,2,1)) -> CUBETA 10 | D13: ERENDIRA MARLENE GOMEZ RIVAS | E13: BO | F13: 00000757 | G13: 08/10/2024 | H13: 2 | I13: 2 | J13: =+H13-I13 -> 0 | O13: =(H13)/(IF(A13="","-",VLOOKUP(A13,'[1]CATALOGO PZXCAJA'!$A$2:$C$5000,2,0))) -> 0.16666667
A14: Producto: 2111001427010101 / BISA CUBETA 12 NEGRO MOTAS | B14: =+MID(A14,13,6) -> 110014 | C14: =_xlfn.CONCAT(+VLOOKUP(VALUE(MID(A14,13,2)),'Tabla de codigos'!$A$2:$B$60,2,1)," ",VLOOKUP(VALUE(MID(A14,15,4)),'Tabla de codigos'!$E$2:$F$102,2,1)) -> CUBETA 12 | D14: ERENDIRA MARLENE GOMEZ RIVAS | E14: BO | F14: 00000757 | G14: 08/10/2024 | H14: 24 | I14: 24 | J14: =+H14-I14 -> 0 | O14: =(H14)/(IF(A14="","-",VLOOKUP(A14,'[1]CATALOGO PZXCAJA'!$A$2:$C$5000,2,0))) -> 2
A15: Producto: 2111001527010101 / BISA CUBETA 14 NEGRO MOTAS | B15: =+MID(A15,13,6) -> 110015 | C15: =_xlfn.CONCAT(+VLOOKUP(VALUE(MID(A15,13,2)),'Tabla de codigos'!$A$2:$B$60,2,1)," ",VLOOKUP(VALUE(MID(A15,15,4)),'Tabla de codigos'!$E$2:$F$102,2,1)) -> CUBETA 14 | D15: ERENDIRA MARLENE GOMEZ RIVAS | E15: BO | F15: 00000757 | G15: 08/10/2024 | H15: 16 | I15: 16 | J15: =+H15-I15 -> 0 | O15: =(H15)/(IF(A15="","-",VLOOKUP(A15,'[1]CATALOGO PZXCAJA'!$A$2:$C$5000,2,0))) -> 1.3333333
A16: Producto: 2124002402010101 / BISA OLLA CONVEXA 22 A/T | B16: =+MID(A16,13,6) -> 240024 | C16: =_xlfn.CONCAT(+VLOOKUP(VALUE(MID(A16,13,2)),'Tabla de codigos'!$A$2:$B$60,2,1)," ",VLOOKUP(VALUE(MID(A16,15,4)),'Tabla de codigos'!$E$2:$F$102,2,1)) -> OLLA CONVEXA 22 | D16: ERENDIRA MARLENE GOMEZ RIVAS | E16: BO | F16: 00000757 | G16: 08/10/2024 | H16: 6 | I16: 6 | J16: =+H16-I16 -> 0 | O16: =(H16)/(IF(A16="","-",VLOOKUP(A16,'[1]CATALOGO PZXCAJA'!$A$2:$C$5000,2,0))) -> 1
A17: Producto: 2136002502010101 / BISA SARTEN 24 A/T | B17: =+MID(A17,13,6) -> 360025 | C17: =_xlfn.CONCAT(+VLOOKUP(VALUE(MID(A17,13,2)),'Tabla de codigos'!$A$2:$B$60,2,1)," ",VLOOKUP(VALUE(MID(A17,15,4)),'Tabla de codigos'!$E$2:$F$102,2,1)) -> SARTEN 24 | D17: ERENDIRA MARLENE GOMEZ RIVAS | E17: BO | F17: 00000757 | G17: 08/10/2024 | H17: 36 | I17: 3 | J17: =+H17-I17 -> 33 | K17: =(SUM(I11:I17))/(SUM(H11:H17)) -> 0.625 | O17: =(H17)/(IF(A17="","-",VLOOKUP(A17,'[1]CATALOGO PZXCAJA'!$A$2:$C$5000,2,0))) -> 3
A18: Producto: 1103000819010101 / BISA BAÑO 4 GALVANIZADO | B18: =+MID(A18,13,6) -> 030008 | C18: =_xlfn.CONCAT(+VLOOKUP(VALUE(MID(A18,13,2)),'Tabla de codigos'!$A$2:$B$60,2,1)," ",VLOOKUP(VALUE(MID(A18,15,4)),'Tabla de codigos'!$E$2:$F$102,2,1)) -> BAÑO 4 | D18: EVELIA MELCHOR | E18: BO | F18: 00000765 | G18: 02/12/2024 | H18: 50 | I18: 0 | J18: =+H18-I18 -> 50 | O18: =(H18)/(IF(A18="","-",VLOOKUP(A18,'[1]CATALOGO PZXCAJA'!$A$2:$C$5000,2,0))) -> #N/A
A19: Producto: 1103000919010101 / BISA BAÑO 5 GALVANIZADO | B19: =+MID(A19,13,6) -> 030009 | C19: =_xlfn.CONCAT(+VLOOKUP(VALUE(MID(A19,13,2)),'Tabla de codigos'!$A$2:$B$60,2,1)," ",VLOOKUP(VALUE(MID(A19,15,4)),'Tabla de codigos'!$E$2:$F$102,2,1)) -> BAÑO 5 | D19: EVELIA MELCHOR | E19: BO | F19: 00000765 | G19: 02/12/2024 | H19: 100 | I19: 0 | J19: =+H19-I19 -> 100 | O19: =(H19)/(IF(A19="","-",VLOOKUP(A19,'[1]CATALOGO PZXCAJA'!$A$2:$C$5000,2,0))) -> #N/A
A20: Producto: 1111001219010101 / BISA CUBETA 8 GALVANIZADO | B20: =+MID(A20,13,6) -> 110012 | C20: =_xlfn.CONCAT(+VLOOKUP(VALUE(MID(A20,13,2)),'Tabla de codigos'!$A$2:$B$60,2,1)," ",VLOOKUP(VALUE(MID(A20,15,4)),'Tabla de codigos'!$E$2:$F$102,2,1)) -> CUBETA 8 | D20: EVELIA MELCHOR | E20: BO | F20: 00000765 | G20: 02/12/2024 | H20: 25 | I20: 0 | J20: =+H20-I20 -> 25 | O20: =(H20)/(IF(A20="","-",VLOOKUP(A20,'[1]CATALOGO PZXCAJA'!$A$2:$C$5000,2,0))) -> #N/A
A21: Producto: 1111001419010101 / BISA CUBETA 12 GALVANIZADO | B21: =+MID(A21,13,6) -> 110014 | C21: =_xlfn.CONCAT(+VLOOKUP(VALUE(MID(A21,13,2)),'Tabla de codigos'!$A$2:$B$60,2,1)," ",VLOOKUP(VALUE(MID(A21,15,4)),'Tabla de codigos'!$E$2:$F$102,2,1)) -> CUBETA 12 | D21: EVELIA MELCHOR | E21: BO | F21: 00000765 | G21: 02/12/2024 | H21: 50 | I21: 50 | J21: =+H21-I21 -> 0 | K21: =(SUM(I18:I21))/(SUM(H18:H21)) -> 0.22222222 | O21: =(H21)/(IF(A21="","-",VLOOKUP(A21,'[1]CATALOGO PZXCAJA'!$A$2:$C$5000,2,0))) -> #N/A
A22: Producto: 2111000927010101 / BISA CUBETA 5 NEGRO MOTAS | B22: =+MID(A22,13,6) -> 110009 | C22: =_xlfn.CONCAT(+VLOOKUP(VALUE(MID(A22,13,2)),'Tabla de codigos'!$A$2:$B$60,2,1)," ",VLOOKUP(VALUE(MID(A22,15,4)),'Tabla de codigos'!$E$2:$F$102,2,1)) -> CUBETA 5 | D22: GASTROART | E22: VT1 | F22: 00003536 | G22: 14/03/2025 | H22: 24 | I22: 0 | J22: =+H22-I22 -> 24
A23: Producto: 2133000927010101 / BISA POCILLO 5 NEGRO MOTAS | B23: =+MID(A23,13,6) -> 330009 | C23: =_xlfn.CONCAT(+VLOOKUP(VALUE(MID(A23,13,2)),'Tabla de codigos'!$A$2:$B$60,2,1)," ",VLOOKUP(VALUE(MID(A23,15,4)),'Tabla de codigos'!$E$2:$F$102,2,1)) -> POCILLO 5 | D23: GASTROART | E23: VT1 | F23: 00003536 | G23: 14/03/2025 | H23: 144 | I23: 144 | J23: =+H23-I23 -> 0 | K23: =(SUM(I22:I23))/(SUM(H22:H23)) -> 0.85714286
A24: Producto: 2108002117010101 / BISA CAZUELA 18 COBALTO | B24: =+MID(A24,13,6) -> 080021 | C24: =_xlfn.CONCAT(+VLOOKUP(VALUE(MID(A24,13,2)),'Tabla de codigos'!$A$2:$B$60,2,1)," ",VLOOKUP(VALUE(MID(A24,15,4)),'Tabla de codigos'!$E$2:$F$102,2,1)) -> CAZUELA 18 | D24: GRUPO EMPRESARIAL | E24: BO | F24: 00000793 | G24: 11/04/2025 | H24: 48 | I24: 6 | J24: =+H24-I24 -> 42
A25: Producto: 2108002121010101 / BISA CAZUELA 18 GRIS | B25: =+MID(A25,13,6) -> 080021 | C25: =_xlfn.CONCAT(+VLOOKUP(VALUE(MID(A25,13,2)),'Tabla de codigos'!$A$2:$B$60,2,1)," ",VLOOKUP(VALUE(MID(A25,15,4)),'Tabla de codigos'!$E$2:$F$102,2,1)) -> CAZUELA 18 | D25: GRUPO EMPRESARIAL | E25: BO | F25: 00000793 | G25: 11/04/2025 | H25: 48 | I25: =5+7+12 -> 24 | J25: =+H25-I25 -> 24
A26: Producto: 2108002129010101 / BISA CAZUELA 18 ROJO | B26: =+MID(A26,13,6) -> 080021 | C26: =_xlfn.CONCAT(+VLOOKUP(VALUE(MID(A26,13,2)),'Tabla de codigos'!$A$2:$B$60,2,1)," ",VLOOKUP(VALUE(MID(A26,15,4)),'Tabla de codigos'!$E$2:$F$102,2,1)) -> CAZUELA 18 | D26: GRUPO EMPRESARIAL | E26: BO | F26: 00000793 | G26: 11/04/2025 | H26: 36 | I26: 2 | J26: =+H26-I26 -> 34
A27: Producto: 2108002517010101 / BISA CAZUELA 24 COBALTO | B27: =+MID(A27,13,6) -> 080025 | C27: =_xlfn.CONCAT(+VLOOKUP(VALUE(MID(A27,13,2)),'Tabla de codigos'!$A$2:$B$60,2,1)," ",VLOOKUP(VALUE(MID(A27,15,4)),'Tabla de codigos'!$E$2:$F$102,2,1)) -> CAZUELA 24 | D27: GRUPO EMPRESARIAL | E27: BO | F27: 00000793 | G27: 11/04/2025 | H27: 24 | I27: 0 | J27: =+H27-I27 -> 24
A28: Producto: 2108002521010101 / BISA CAZUELA 24 GRIS | B28: =+MID(A28,13,6) -> 080025 | C28: =_xlfn.CONCAT(+VLOOKUP(VALUE(MID(A28,13,2)),'Tabla de codigos'!$A$2:$B$60,2,1)," ",VLOOKUP(VALUE(MID(A28,15,4)),'Tabla de codigos'!$E$2:$F$102,2,1)) -> CAZUELA 24 | D28: GRUPO EMPRESARIAL | E28: BO | F28: 00000793 | G28: 11/04/2025 | H28: 24 | I28: 0 | J28: =+H28-I28 -> 24
A29: Producto: 2108002529010101 / BISA CAZUELA 24 ROJO | B29: =+MID(A29,13,6) -> 080025 | C29: =_xlfn.CONCAT(+VLOOKUP(VALUE(MID(A29,13,2)),'Tabla de codigos'!$A$2:$B$60,2,1)," ",VLOOKUP(VALUE(MID(A29,15,4)),'Tabla de codigos'!$E$2:$F$102,2,1)) -> CAZUELA 24 | D29: GRUPO EMPRESARIAL | E29: BO | F29: 00000793 | G29: 11/04/2025 | H29: 24 | I29: 1 | J29: =+H29-I29 -> 23
A30: Producto: 2123001816050101 / RECIPIENTE MULTIUSOS RAYADO 15.5 BLANCO C/F NEGRO | B30: =+MID(A30,13,6) -> 230018 | C30: =_xlfn.CONCAT(+VLOOKUP(VALUE(MID(A30,13,2)),'Tabla de codigos'!$A$2:$B$60,2,1)," ",VLOOKUP(VALUE(MID(A30,15,4)),'Tabla de codigos'!$E$2:$F$102,2,1)) -> MULTIUSOS RAYADO 16.5 | D30: GRUPO EMPRESARIAL | E30: BO | F30: 00000793 | G30: 11/04/2025 | H30: 12 | I30: 1 | J30: =+H30-I30 -> 11
A31: Producto: 2126002202010101 / BISA PLATO AVENERO 20 A/T | B31: =+MID(A31,13,6) -> 260022 | C31: =_xlfn.CONCAT(+VLOOKUP(VALUE(MID(A31,13,2)),'Tabla de codigos'!$A$2:$B$60,2,1)," ",VLOOKUP(VALUE(MID(A31,15,4)),'Tabla de codigos'!$E$2:$F$102,2,1)) -> PLATO AVENERO 20 | D31: GRUPO EMPRESARIAL | E31: BO | F31: 00000793 | G31: 11/04/2025 | H31: 120 | I31: =91+29 -> 120 | J31: =+H31-I31 -> 0
A32: Producto: 2128001726010101 / BISA PLATO BISTRO 16 NEGRO | B32: =+MID(A32,13,6) -> 280017 | C32: =_xlfn.CONCAT(+VLOOKUP(VALUE(MID(A32,13,2)),'Tabla de codigos'!$A$2:$B$60,2,1)," ",VLOOKUP(VALUE(MID(A32,15,4)),'Tabla de codigos'!$E$2:$F$102,2,1)) -> PLATO BISTRO 16 | D32: GRUPO EMPRESARIAL | E32: BO | F32: 00000793 | G32: 11/04/2025 | H32: 12 | I32: 4 | J32: =+H32-I32 -> 8
A33: Producto: 2130001730010101 / BISA PLATO LISO 16 ROJO MOTAS | B33: =+MID(A33,13,6) -> 300017 | C33: =_xlfn.CONCAT(+VLOOKUP(VALUE(MID(A33,13,2)),'Tabla de codigos'!$A$2:$B$60,2,1)," ",VLOOKUP(VALUE(MID(A33,15,4)),'Tabla de codigos'!$E$2:$F$102,2,1)) -> PLATO LISO 16 | D33: GRUPO EMPRESARIAL | E33: BO | F33: 00000793 | G33: 11/04/2025 | H33: 30 | I33: 0 | J33: =+H33-I33 -> 30
A34: Producto: 2130002516050101 / BISA PLATO LISO 24 BLANCO C/F NEGRO | B34: =+MID(A34,13,6) -> 300025 | C34: =_xlfn.CONCAT(+VLOOKUP(VALUE(MID(A34,13,2)),'Tabla de codigos'!$A$2:$B$60,2,1)," ",VLOOKUP(VALUE(MID(A34,15,4)),'Tabla de codigos'!$E$2:$F$102,2,1)) -> PLATO LISO 24 | D34: GRUPO EMPRESARIAL | E34: BO | F34: 00000793 | G34: 11/04/2025 | H34: 24 | I34: 24 | J34: =+H34-I34 -> 0
A35: Producto: 2130002516070101 / BISA PLATO LISO 24 BLANCO C/F ROJO | B35: =+MID(A35,13,6) -> 300025 | C35: =_xlfn.CONCAT(+VLOOKUP(VALUE(MID(A35,13,2)),'Tabla de codigos'!$A$2:$B$60,2,1)," ",VLOOKUP(VALUE(MID(A35,15,4)),'Tabla de codigos'!$E$2:$F$102,2,1)) -> PLATO LISO 24 | D35: GRUPO EMPRESARIAL | E35: BO | F35: 00000793 | G35: 11/04/2025 | H35: 6 | I35: 0 | J35: =+H35-I35 -> 6
A36: Producto: 2130002716040101 / BISA PLATO LISO 27 BLANCO C/F GRIS | B36: =+MID(A36,13,6) -> 300027 | C36: =_xlfn.CONCAT(+VLOOKUP(VALUE(MID(A36,13,2)),'Tabla de codigos'!$A$2:$B$60,2,1)," ",VLOOKUP(VALUE(MID(A36,15,4)),'Tabla de codigos'!$E$2:$F$102,2,1)) -> PLATO LISO 27 | D36: GRUPO EMPRESARIAL | E36: BO | F36: 00000793 | G36: 11/04/2025 | H36: 24 | I36: 12 | J36: =+H36-I36 -> 12
A37: Producto: 2130002716050101 / BISA PLATO LISO 27 BLANCO C/F NEGRO | B37: =+MID(A37,13,6) -> 300027 | C37: =_xlfn.CONCAT(+VLOOKUP(VALUE(MID(A37,13,2)),'Tabla de codigos'!$A$2:$B$60,2,1)," ",VLOOKUP(VALUE(MID(A37,15,4)),'Tabla de codigos'!$E$2:$F$102,2,1)) -> PLATO LISO 27 | D37: GRUPO EMPRESARIAL | E37: BO | F37: 00000793 | G37: 11/04/2025 | H37: 30 | I37: 30 | J37: =+H37-I37 -> 0
A38: Producto: 2133000902010101 / BISA POCILLO 5 A/T | B38: =+MID(A38,13,6) -> 330009 | C38: =_xlfn.CONCAT(+VLOOKUP(VALUE(MID(A38,13,2)),'Tabla de codigos'!$A$2:$B$60,2,1)," ",VLOOKUP(VALUE(MID(A38,15,4)),'Tabla de codigos'!$E$2:$F$102,2,1)) -> POCILLO 5 | D38: GRUPO EMPRESARIAL | E38: BO | F38: 00000793 | G38: 11/04/2025 | H38: 120 | I38: =12+96+12 -> 120 | J38: =+H38-I38 -> 0
A39: Producto: 2133000916040101 / BISA POCILLO 5 BLANCO C/F GRIS | B39: =+MID(A39,13,6) -> 330009 | C39: =_xlfn.CONCAT(+VLOOKUP(VALUE(MID(A39,13,2)),'Tabla de codigos'!$A$2:$B$60,2,1)," ",VLOOKUP(VALUE(MID(A39,15,4)),'Tabla de codigos'!$E$2:$F$102,2,1)) -> POCILLO 5 | D39: GRUPO EMPRESARIAL | E39: BO | F39: 00000793 | G39: 11/04/2025 | H39: 120 | I39: =3+117 -> 120 | J39: =+H39-I39 -> 0
A40: Producto: 2133000916050101 / BISA POCILLO 5 BLANCO C/F NEGRO | B40: =+MID(A40,13,6) -> 330009 | C40: =_xlfn.CONCAT(+VLOOKUP(VALUE(MID(A40,13,2)),'Tabla de codigos'!$A$2:$B$60,2,1)," ",VLOOKUP(VALUE(MID(A40,15,4)),'Tabla de codigos'!$E$2:$F$102,2,1)) -> POCILLO 5 | D40: GRUPO EMPRESARIAL | E40: BO | F40: 00000793 | G40: 11/04/2025 | H40: 120 | I40: =51+69 -> 120 | J40: =+H40-I40 -> 0
...

Sheet Tabla de codigos
A1: ARTICULO --00 | E1: MODELO ----0000 | H1: COLOR ---- ---- 00-- | K1: FILETE ---- ---- --00
A2: 1 | B2: BACINICA | E2: 1 | F2: S/I | H2: 1 | I2: S/I | K2: 1 | L2: S/I
A3: 2 | B3: BANDEJA | E3: 2 | F3: 0 | H3: 2 | I3: A/T | K3: 2 | L3: AQUA
A4: 3 | B4: BAÑO | E4: 3 | F4: 0 | H4: 3 | I4: AMARILLO | K4: 3 | L4: COBALTO
A5: 4 | B5: BATERIA | E5: 4 | F5: 0 | H5: 4 | I5: AMBAR | K5: 4 | L5: GRIS
A6: 5 | B6: BOTE BASURA | E6: 5 | F6: 1 | H6: 5 | I6: AQUA | K6: 5 | L6: NEGRO
A7: 6 | B7: BUDINERA | E7: 6 | F7: 2 | H7: 6 | I7: AZUL | K7: 6 | L7: NEVADO
A8: 7 | B8: CAZO | E8: 7 | F8: 3 | H8: 7 | I8: BERENJENA | K8: 7 | L8: ROJO
A9: 8 | B9: CAZUELA | E9: 8 | F9: 4 | H9: 8 | I9: BICOLOR | K9: 8 | L9: ROSA
A10: 9 | B10: CHAROLA DE SERVICIO | E10: 9 | F10: 5 | H10: 9 | I10: BICOLOR AMARILLO | K10: 9 | L10: VERDE
A11: 10 | B11: COMAL | E11: 10 | F11: 6 | H11: 10 | I11: BICOLOR AZUL | K11: 10 | L11: AZUL
A12: 11 | B12: CUBETA | E12: 11 | F12: 7 | H12: 11 | I12: BICOLOR COBALTO | K12: 11 | L12: CAFÉ
A13: 12 | B13: CUCHARA | E13: 12 | F13: 8 | H13: 12 | I13: BICOLOR NARANJA
A14: 13 | B14: CUCHILLO | E14: 13 | F14: 10 | H14: 13 | I14: BICOLOR NEGRO MOTAS
A15: 14 | B15: DESPACHADOR AGUA | E15: 14 | F15: 12 | H15: 14 | I15: BICOLOR ROJO
A16: 15 | B16: ENSALADERA | E16: 15 | F16: 14 | H16: 15 | I16: BICOLOR VERDE
A17: 16 | B17: FLORERO | E17: 16 | F17: 15.5 | H17: 16 | I17: BLANCO
A18: 17 | B18: FRESH CONTENEDOR | E18: 17 | F18: 16 | H18: 17 | I18: COBALTO
A19: 18 | B19: FUENTE PARA HORNO | E19: 18 | F19: 16.5 | H19: 18 | I19: COBALTO MOTAS
A20: 19 | B20: JARRA RECTA | E20: 19 | F20: 17 | H20: 19 | I20: GALVANIZADO
A21: 20 | B21: JICARA | E21: 20 | F21: 17.5 | H21: 20 | I21: GENERICO
A22: 21 | B22: JUEGO | E22: 21 | F22: 18 | H22: 21 | I22: GRIS
A23: 22 | B23: MULTIUSOS | E23: 22 | F23: 20 | H23: 22 | I23: HUMO
A24: 23 | B24: MULTIUSOS RAYADO | E24: 23 | F24: 20.5 | H24: 23 | I24: NARANJA
... A37: 36 | B37: SARTEN | E37: 36 | F37: 5250 | H37: 36 | I37: TRASLUCIDO AZUL
A38: 37 | B38: TAMALERA | E38: 37 | F38: 2.5 LTS | H38: 37 | I38: TRASLUCIDO AZUL REY
A39: 38 | B39: TAZA BISTRO | E39: 38 | F39: 19 LTS | H39: 38 | I39: TRASLUCIDO BERENJENA
A40: 39 | B40: TAZON | E40: 39 | F40: 75 LTS | H40: 39 | I40: TRASLUCIDO HUMO
A41: 40 | B41: TAZON INCLINADO | E41: 40 | F41: 400 ML | H41: 40 | I41: TRASLUCIDO MORADO
A42: 41 | B42: TENEDOR | E42: 41 | F42: 500 ML | H42: 41 | I42: TRASLUCIDO ROJO
A43: 42 | B43: TORTILLERO | E43: 42 | F43: 1500 ML | H43: 42 | I43: TRASLUCIDO ROSA
A44: 43 | B44: VAJILLA | E44: 43 | F44: 3+3 | H44: 43 | I44: TRASLUCIDO A/T
A45: 44 | B45: VAPORERA | E45: 44 | F45: 5+5 | H45: 44 | I45: TRASLUCIDO VERDE
A46: 45 | B46: VASO | E46: 45 | F46: 30X20 | H46: 45 | I46: TRASLUCIDO VERDE BOTELLA
A47: 46 | B47: VASO AGUA | E47: 46 | F47: 40X30 | H47: 46 | I47: TRIGO/CREMA
A48: 47 | B48: VASO OLD FASHION | E48: 47 | F48: A | H48: 47 | I48: VERDE
A49: 48 | B49: VASO RECTO | E49: 48 | F49: B | H49: 48 | I49: VERDE BOTELLA
... A60: 59 | B60: CUBETA SIN ASA SIN OREJA | E60: 59 | F60: BISTRO | H60: 59 | I60: ARENA
E61: 60 | F61: BODEGON | H61: 60 | I61: NEGRO PIEDRA
E62: 61 | F62: CAMPESTRE | H62: 61 | I62: ENCORE
...

Sheet Hoja 1
A1: FECHA VENTAS | B1: =+TODAY() -> 46109 | C1: DESCRIPCION | D1: PRODUCTO | E1: COLOR | F1: CLIENTE | G1: Serie documento | H1: DOCUMENTO | I1: FECHA CAPTURA | J1: Cantidad | K1: EXISTENTE | L1: PEDIDO FALTANTE | M1: % | N1: FECHA DE VENTAS | O1: PRODUCCION | P1: FECHA LOGISTICA | Q1: DIRECCION DE ENTREGA
A2: =DAYS360(I2,$B$1) -> 205 | B2: =DAYS360($B$1,P3) -> -45448 | C2: Producto: 2133001402010101 / BISA POCILLO 12 A/T | D2: =VLOOKUP(VALUE(MID($C2,13,2)), codigos!$A$2:$B$60, 2, 1) & " " & VLOOKUP(VALUE(MID($C2,15,4)), codigos!$E$2:$F$102, 2, FALSE) -> POCILLO 12 | E2: =VLOOKUP(VALUE(MID($C2,19,2)),codigos!$H$2:$I$62,2,1) & " " & VLOOKUP(VALUE(MID($C2,21,2)),codigos!$K$2:$L$12,2,FALSE) -> A/T S/I | F2: EL MESTIZO LA MEJOR | G2: BO | H2: 00000895 | I2: 03/09/2025 | J2: 396 | K2: =114+2+276+4 -> 396 | L2: =+J2-K2 -> 0 | M2: =(SUM(K2:K5))/(SUM(J2:J5)) -> 0.64655172
A3: =DAYS360(I3,$B$1) -> 156 | B3: =DAYS360($B$1,P4) -> -45448 | C3: Producto: 2106003102010101 / BISA BUDINERA 34 A/T | D3: =VLOOKUP(VALUE(MID($C3,13,2)), codigos!$A$2:$B$60, 2, 1) & " " & VLOOKUP(VALUE(MID($C3,15,4)), codigos!$E$2:$F$102, 2, FALSE) -> BUDINERA 34 | E3: =VLOOKUP(VALUE(MID($C3,19,2)),codigos!$H$2:$I$62,2,1) & " " & VLOOKUP(VALUE(MID($C3,21,2)),codigos!$K$2:$L$12,2,FALSE) -> A/T S/I | F3: EL MESTIZO LA MEJOR | G3: BO | H3: 00000895 | I3: 22/10/2025 | J3: 100 | K3: 0 | L3: =+J3-K3 -> 100
A4: =DAYS360(I4,$B$1) -> 156 | B4: =DAYS360($B$1,P5) -> -45448 | C4: Producto: 2121004301010101 / BISA JUEGO 3+3 | D4: =VLOOKUP(VALUE(MID($C4,13,2)), codigos!$A$2:$B$60, 2, 1) & " " & VLOOKUP(VALUE(MID($C4,15,4)), codigos!$E$2:$F$102, 2, FALSE) -> JUEGO 3+3 | E4: =VLOOKUP(VALUE(MID($C4,19,2)),codigos!$H$2:$I$62,2,1) & " " & VLOOKUP(VALUE(MID($C4,21,2)),codigos!$K$2:$L$12,2,FALSE) -> S/I S/I | F4: EL MESTIZO LA MEJOR | G4: BO | H4: 00000895 | I4: 22/10/2025 | J4: 448 | K4: =179 -> 179 | L4: =+J4-K4 -> 269
A5: =DAYS360(I5,$B$1) -> 156 | B5: =DAYS360($B$1,P6) -> -45448 | C5: Producto: 2125003102010101 / BISA OLLA RECTA 34 A/T | D5: =VLOOKUP(VALUE(MID($C5,13,2)), codigos!$A$2:$B$60, 2, 1) & " " & VLOOKUP(VALUE(MID($C5,15,4)), codigos!$E$2:$F$102, 2, FALSE) -> OLLA RECTA 34 | E5: =VLOOKUP(VALUE(MID($C5,19,2)),codigos!$H$2:$I$62,2,1) & " " & VLOOKUP(VALUE(MID($C5,21,2)),codigos!$K$2:$L$12,2,FALSE) -> A/T S/I | F5: EL MESTIZO LA MEJOR | G5: BO | H5: 00000895 | I5: 22/10/2025 | J5: 100 | K5: =20+2-6+12+48+4+20 -> 100 | L5: =+J5-K5 -> 0
A6: =DAYS360(I6,$B$1) -> 60 | B6: =DAYS360($B$1,P7) -> -45448 | C6: Producto: 2106002202010101 / BISA BUDINERA 20 A/T | D6: =VLOOKUP(VALUE(MID($C6,13,2)), codigos!$A$2:$B$60, 2, 1) & " " & VLOOKUP(VALUE(MID($C6,15,4)), codigos!$E$2:$F$102, 2, FALSE) -> BUDINERA 20 | E6: =VLOOKUP(VALUE(MID($C6,19,2)),codigos!$H$2:$I$62,2,1) & " " & VLOOKUP(VALUE(MID($C6,21,2)),codigos!$K$2:$L$12,2,FALSE) -> A/T S/I | F6: GRUPO EMPRESARIAL TENORIO | G6: VT2 | H6: 00005043 | I6: 28/01/2026 | J6: 180 | K6: =59+36+1+13+56+15 -> 180 | L6: =+J6-K6 -> 0 | M6: =(SUM(K6:K24))/(SUM(J6:J24)) -> 0.81985044 | O6: 46108
A7: =DAYS360(I7,$B$1) -> 60 | B7: =DAYS360($B$1,P8) -> -45448 | C7: Producto: 2106002402010101 / BISA BUDINERA 22 A/T | D7: =VLOOKUP(VALUE(MID($C7,13,2)), codigos!$A$2:$B$60, 2, 1) & " " & VLOOKUP(VALUE(MID($C7,15,4)), codigos!$E$2:$F$102, 2, FALSE) -> BUDINERA 22 | E7: =VLOOKUP(VALUE(MID($C7,19,2)),codigos!$H$2:$I$62,2,1) & " " & VLOOKUP(VALUE(MID($C7,21,2)),codigos!$K$2:$L$12,2,FALSE) -> A/T S/I | F7: GRUPO EMPRESARIAL TENORIO | G7: VT2 | H7: 00005043 | I7: 46050 | J7: 180 | K7: =120+12+48-120+6+24+12+72+6-29+29 -> 180 | L7: =+J7-K7 -> 0 | O7: 46108
A8: =DAYS360(I8,$B$1) -> 60 | B8: =DAYS360($B$1,P9) -> -45448 | C8: Producto: 2106002502010101 / BISA BUDINERA 24 A/T | D8: =VLOOKUP(VALUE(MID($C8,13,2)), codigos!$A$2:$B$60, 2, 1) & " " & VLOOKUP(VALUE(MID($C8,15,4)), codigos!$E$2:$F$102, 2, FALSE) -> BUDINERA 24 | E8: =VLOOKUP(VALUE(MID($C8,19,2)),codigos!$H$2:$I$62,2,1) & " " & VLOOKUP(VALUE(MID($C8,21,2)),codigos!$K$2:$L$12,2,FALSE) -> A/T S/I | F8: GRUPO EMPRESARIAL TENORIO | G8: VT2 | H8: 00005043 | I8: 28/01/2026 | J8: 204 | K8: =91+14+4+24 -> 133 | L8: =+J8-K8 -> 71 | O8: 46108
A9: =DAYS360(I9,$B$1) -> 60 | B9: =DAYS360($B$1,P10) -> -45448 | C9: Producto: 2106002602010101 / BISA BUDINERA 26 A/T | D9: =VLOOKUP(VALUE(MID($C9,13,2)), codigos!$A$2:$B$60, 2, 1) & " " & VLOOKUP(VALUE(MID($C9,15,4)), codigos!$E$2:$F$102, 2, FALSE) -> BUDINERA 26 | E9: =VLOOKUP(VALUE(MID($C9,19,2)),codigos!$H$2:$I$62,2,1) & " " & VLOOKUP(VALUE(MID($C9,21,2)),codigos!$K$2:$L$12,2,FALSE) -> A/T S/I | F9: GRUPO EMPRESARIAL TENORIO | G9: VT2 | H9: 00005043 | I9: 28/01/2026 | J9: 120 | K9: =12+36+4+4+1-57 -> 0 | L9: =+J9-K9 -> 120 | O9: 46108
A10: =DAYS360(I10,$B$1) -> 60 | B10: =DAYS360($B$1,P11) -> -45448 | C10: Producto: 2124002202010101 / BISA OLLA CONVEXA 20 A/T | D10: =VLOOKUP(VALUE(MID($C10,13,2)), codigos!$A$2:$B$60, 2, 1) & " " & VLOOKUP(VALUE(MID($C10,15,4)), codigos!$E$2:$F$102, 2, FALSE) -> OLLA CONVEXA 20 | E10: =VLOOKUP(VALUE(MID($C10,19,2)),codigos!$H$2:$I$62,2,1) & " " & VLOOKUP(VALUE(MID($C10,21,2)),codigos!$K$2:$L$12,2,FALSE) -> A/T S/I | F10: GRUPO EMPRESARIAL TENORIO | G10: VT2 | H10: 00005043 | I10: 28/01/2026 | J10: 180 | K10: =180 -> 180 | L10: =+J10-K10 -> 0 | O10: 46108
A11: =DAYS360(I11,$B$1) -> 60 | B11: =DAYS360($B$1,P12) -> -45448 | C11: Producto: 2124002402010101 / BISA OLLA CONVEXA 22 A/T | D11: =VLOOKUP(VALUE(MID($C11,13,2)), codigos!$A$2:$B$60, 2, 1) & " " & VLOOKUP(VALUE(MID($C11,15,4)), codigos!$E$2:$F$102, 2, FALSE) -> OLLA CONVEXA 22 | E11: =VLOOKUP(VALUE(MID($C11,19,2)),codigos!$H$2:$I$62,2,1) & " " & VLOOKUP(VALUE(MID($C11,21,2)),codigos!$K$2:$L$12,2,FALSE) -> A/T S/I | F11: GRUPO EMPRESARIAL TENORIO | G11: VT2 | H11: 00005043 | I11: 28/01/2026 | J11: 180 | K11: =4+108+6+6+12+6+1+36+1-120+1+4+114+1 -> 180 | L11: =+J11-K11 -> 0 | O11: 46108
A12: =DAYS360(I12,$B$1) -> 60 | B12: =DAYS360($B$1,P13) -> -45448 | C12: Producto: 2124002502010101 / BISA OLLA CONVEXA 24 A/T | D12: =VLOOKUP(VALUE(MID($C12,13,2)), codigos!$A$2:$B$60, 2, 1) & " " & VLOOKUP(VALUE(MID($C12,15,4)), codigos!$E$2:$F$102, 2, FALSE) -> OLLA CONVEXA 24 | E12: =VLOOKUP(VALUE(MID($C12,19,2)),codigos!$H$2:$I$62,2,1) & " " & VLOOKUP(VALUE(MID($C12,21,2)),codigos!$K$2:$L$12,2,FALSE) -> A/T S/I | F12: GRUPO EMPRESARIAL TENORIO | G12: VT2 | H12: 00005043 | I12: 28/01/2026 | J12: 150 | K12: =2+102+30+6-120+18+6+3+2+12+5+18+3-60+18+24+6+75 -> 150 | L12: =+J12-K12 -> 0 | O12: 46108
A13: =DAYS360(I13,$B$1) -> 60 | B13: =DAYS360($B$1,P14) -> -45448 | C13: Producto: 2124002902010101 / BISA OLLA CONVEXA 30 A/T | D13: =VLOOKUP(VALUE(MID($C13,13,2)), codigos!$A$2:$B$60, 2, 1) & " " & VLOOKUP(VALUE(MID($C13,15,4)), codigos!$E$2:$F$102, 2, FALSE) -> OLLA CONVEXA 30 | E13: =VLOOKUP(VALUE(MID($C13,19,2)),codigos!$H$2:$I$62,2,1) & " " & VLOOKUP(VALUE(MID($C13,21,2)),codigos!$K$2:$L$12,2,FALSE) -> A/T S/I | F13: GRUPO EMPRESARIAL TENORIO | G13: VT2 | H13: 00005043 | I13: 28/01/2026 | J13: 120 | K13: =66+22+8 -> 96 | L13: =+J13-K13 -> 24 | O13: 46108
A14: =DAYS360(I14,$B$1) -> 60 | B14: =DAYS360($B$1,P15) -> -45448 | C14: Producto: 2124003102010101 / BISA OLLA CONVEXA 34 A/T | D14: =VLOOKUP(VALUE(MID($C14,13,2)), codigos!$A$2:$B$60, 2, 1) & " " & VLOOKUP(VALUE(MID($C14,15,4)), codigos!$E$2:$F$102, 2, FALSE) -> OLLA CONVEXA 34 | E14: =VLOOKUP(VALUE(MID($C14,19,2)),codigos!$H$2:$I$62,2,1) & " " & VLOOKUP(VALUE(MID($C14,21,2)),codigos!$K$2:$L$12,2,FALSE) -> A/T S/I | F14: GRUPO EMPRESARIAL TENORIO | G14: VT2 | H14: 00005043 | I14: 28/01/2026 | J14: 120 | K14: 120 | L14: =+J14-K14 -> 0 | O14: 46108
A15: =DAYS360(I15,$B$1) -> 60 | B15: =DAYS360($B$1,P16) -> -45448 | C15: Producto: 2125003302010101 / BISA OLLA RECTA 42 A/T | D15: =VLOOKUP(VALUE(MID($C15,13,2)), codigos!$A$2:$B$60, 2, 1) & " " & VLOOKUP(VALUE(MID($C15,15,4)), codigos!$E$2:$F$102, 2, FALSE) -> OLLA RECTA 42 | E15: =VLOOKUP(VALUE(MID($C15,19,2)),codigos!$H$2:$I$62,2,1) & " " & VLOOKUP(VALUE(MID($C15,21,2)),codigos!$K$2:$L$12,2,FALSE) -> A/T S/I | F15: GRUPO EMPRESARIAL TENORIO | G15: VT2 | H15: 00005043 | I15: 28/01/2026 | J15: 4 | K15: =3+1 -> 4 | L15: =+J15-K15 -> 0 | O15: 46108
A16: =DAYS360(I16,$B$1) -> 60 | B16: =DAYS360($B$1,P17) -> -45448 | C16: Producto: 2133001202010101 / BISA POCILLO 8 A/T | D16: =VLOOKUP(VALUE(MID($C16,13,2)), codigos!$A$2:$B$60, 2, 1) & " " & VLOOKUP(VALUE(MID($C16,15,4)), codigos!$E$2:$F$102, 2, FALSE) -> POCILLO 8 | E16: =VLOOKUP(VALUE(MID($C16,19,2)),codigos!$H$2:$I$62,2,1) & " " & VLOOKUP(VALUE(MID($C16,21,2)),codigos!$K$2:$L$12,2,FALSE) -> A/T S/I | F16: GRUPO EMPRESARIAL TENORIO | G16: VT2 | H16: 00005043 | I16: 28/01/2026 | J16: 240 | K16: =20-12+192+4+24+12-27-96+90 -> 207 | L16: =+J16-K16 -> 33 | O16: 46108
A17: =DAYS360(I17,$B$1) -> 60 | B17: =DAYS360($B$1,P18) -> -45448 | C17: Producto: 2133001302010101 / BISA POCILLO 10 A/T | D17: =VLOOKUP(VALUE(MID($C17,13,2)), codigos!$A$2:$B$60, 2, 1) & " " & VLOOKUP(VALUE(MID($C17,15,4)), codigos!$E$2:$F$102, 2, FALSE) -> POCILLO 10 | E17: =VLOOKUP(VALUE(MID($C17,19,2)),codigos!$H$2:$I$62,2,1) & " " & VLOOKUP(VALUE(MID($C17,21,2)),codigos!$K$2:$L$12,2,FALSE) -> A/T S/I | F17: GRUPO EMPRESARIAL TENORIO | G17: VT2 | H17: 00005043 | I17: 28/01/2026 | J17: 240 | K17: =10+107+24+24+18+48+9-81+81 -> 240 | L17: =+J17-K17 -> 0 | O17: 46108
A18: =DAYS360(I18,$B$1) -> 60 | B18: =DAYS360($B$1,P19) -> -45448 | C18: Producto: 2133001402010101 / BISA POCILLO 12 A/T | D18: =VLOOKUP(VALUE(MID($C18,13,2)), codigos!$A$2:$B$60, 2, 1) & " " & VLOOKUP(VALUE(MID($C18,15,4)), codigos!$E$2:$F$102, 2, FALSE) -> POCILLO 12 | E18: =VLOOKUP(VALUE(MID($C18,19,2)),codigos!$H$2:$I$62,2,1) & " " & VLOOKUP(VALUE(MID($C18,21,2)),codigos!$K$2:$L$12,2,FALSE) -> A/T S/I | F18: GRUPO EMPRESARIAL TENORIO | G18: VT2 | H18: 00005043 | I18: 28/01/2026 | J18: 240 | K18: =10+24+5+48+84+69-117 -> 123 | L18: =+J18-K18 -> 117 | O18: 46108
A19: =DAYS360(I19,$B$1) -> 60 | B19: =DAYS360($B$1,P20) -> -45448 | C19: Producto: 2133001502010101 / BISA POCILLO 14 A/T | D19: =VLOOKUP(VALUE(MID($C19,13,2)), codigos!$A$2:$B$60, 2, 1) & " " & VLOOKUP(VALUE(MID($C19,15,4)), codigos!$E$2:$F$102, 2, FALSE) -> POCILLO 14 | E19: =VLOOKUP(VALUE(MID($C19,19,2)),codigos!$H$2:$I$62,2,1) & " " & VLOOKUP(VALUE(MID($C19,21,2)),codigos!$K$2:$L$12,2,FALSE) -> A/T S/I | F19: GRUPO EMPRESARIAL TENORIO | G19: VT2 | H19: 00005043 | I19: 28/01/2026 | J19: 180 | K19: =53+2 -> 55 | L19: =+J19-K19 -> 125 | O19: 46108
A20: =DAYS360(I20,$B$1) -> 60 | B20: =DAYS360($B$1,P21) -> -45448 | C20: Producto: 2136002202010101 / BISA SARTEN 20 A/T | D20: =VLOOKUP(VALUE(MID($C20,13,2)), codigos!$A$2:$B$60, 2, 1) & " " & VLOOKUP(VALUE(MID($C20,15,4)), codigos!$E$2:$F$102, 2, FALSE) -> SARTEN 20 | E20: =VLOOKUP(VALUE(MID($C20,19,2)),codigos!$H$2:$I$62,2,1) & " " & VLOOKUP(VALUE(MID($C20,21,2)),codigos!$K$2:$L$12,2,FALSE) -> A/T S/I | F20: GRUPO EMPRESARIAL TENORIO | G20: VT2 | H20: 00005043 | I20: 28/01/2026 | J20: 120 | K20: 120 | L20: =+J20-K20 -> 0 | O20: 46108
A21: =DAYS360(I21,$B$1) -> 60 | B21: =DAYS360($B$1,P22) -> -45448 | C21: Producto: 2136002402010101 / BISA SARTEN 22 A/T | D21: =VLOOKUP(VALUE(MID($C21,13,2)), codigos!$A$2:$B$60, 2, 1) & " " & VLOOKUP(VALUE(MID($C21,15,4)), codigos!$E$2:$F$102, 2, FALSE) -> SARTEN 22 | E21: =VLOOKUP(VALUE(MID($C21,19,2)),codigos!$H$2:$I$62,2,1) & " " & VLOOKUP(VALUE(MID($C21,21,2)),codigos!$K$2:$L$12,2,FALSE) -> A/T S/I | F21: GRUPO EMPRESARIAL TENORIO | G21: VT2 | H21: 00005043 | I21: 28/01/2026 | J21: 180 | K21: =24+108-120+12+12+24+7+5+108-108+6+3+3+48+12-4 -> 140 | L21: =+J21-K21 -> 40 | O21: 46108
A22: =DAYS360(I22,$B$1) -> 60 | B22: =DAYS360($B$1,P23) -> -45448 | C22: Producto: 2136002502010101 / BISA SARTEN 24 A/T | D22: =VLOOKUP(VALUE(MID($C22,13,2)), codigos!$A$2:$B$60, 2, 1) & " " & VLOOKUP(VALUE(MID($C22,15,4)), codigos!$E$2:$F$102, 2, FALSE) -> SARTEN 24 | E22: =VLOOKUP(VALUE(MID($C22,19,2)),codigos!$H$2:$I$62,2,1) & " " & VLOOKUP(VALUE(MID($C22,21,2)),codigos!$K$2:$L$12,2,FALSE) -> A/T S/I | F22: GRUPO EMPRESARIAL TENORIO | G22: VT2 | H22: 00005043 | I22: 28/01/2026 | J22: 180 | K22: =120-14+24+3+47-120+1+9+110 -> 180 | L22: =+J22-K22 -> 0 | O22: 46108
A23: =DAYS360(I23,$B$1) -> 60 | B23: =DAYS360($B$1,P24) -> -45448 | C23: Producto: 2136002602010101 / BISA SARTEN 26 A/T | D23: =VLOOKUP(VALUE(MID($C23,13,2)), codigos!$A$2:$B$60, 2, 1) & " " & VLOOKUP(VALUE(MID($C23,15,4)), codigos!$E$2:$F$102, 2, FALSE) -> SARTEN 26 | E23: =VLOOKUP(VALUE(MID($C23,19,2)),codigos!$H$2:$I$62,2,1) & " " & VLOOKUP(VALUE(MID($C23,21,2)),codigos!$K$2:$L$12,2,FALSE) -> A/T S/I | F23: GRUPO EMPRESARIAL TENORIO | G23: VT2 | H23: 00005043 | I23: 28/01/2026 | J23: 120 | K23: 120 | L23: =+J23-K23 -> 0 | O23: 46108
A24: =DAYS360(I24,$B$1) -> 60 | B24: =DAYS360($B$1,#REF!) -> #REF! | C24: Producto: 2125009902010101 / BISA OLLA RECTA 38 A/T | D24: =VLOOKUP(VALUE(MID($C24,13,2)), codigos!$A$2:$B$60, 2, 1) & " " & VLOOKUP(VALUE(MID($C24,15,4)), codigos!$E$2:$F$102, 2, FALSE) -> OLLA RECTA 38 | E24: =VLOOKUP(VALUE(MID($C24,19,2)),codigos!$H$2:$I$62,2,1) & " " & VLOOKUP(VALUE(MID($C24,21,2)),codigos!$K$2:$L$12,2,FALSE) -> A/T S/I | F24: GRUPO EMPRESARIAL TENORIO | G24: VT2 | H24: 00005043 | I24: 28/01/2026 | J24: 4 | K24: 4 | L24: =+J24-K24 -> 0 | O24: 46108
A25: =DAYS360(I25,$B$1) -> 148 | B25: =DAYS360($B$1,P26) -> -45448 | C25: Producto: 2106002902010101 / BISA BUDINERA 30 A/T | D25: =VLOOKUP(VALUE(MID($C25,13,2)), codigos!$A$2:$B$60, 2, 1) & " " & VLOOKUP(VALUE(MID($C25,15,4)), codigos!$E$2:$F$102, 2, FALSE) -> BUDINERA 30 | E25: =VLOOKUP(VALUE(MID($C25,19,2)),codigos!$H$2:$I$62,2,1) & " " & VLOOKUP(VALUE(MID($C25,21,2)),codigos!$K$2:$L$12,2,FALSE) -> A/T S/I | F25: MA DE LOS ANGELES | G25: BO | H25: 00000909 | I25: 30/10/2025 | J25: 40 | K25: =8+12+20 -> 40 | L25: =+J25-K25 -> 0 | M25: =(SUM(K25:K29))/(SUM(J25:J29)) -> 1 | O25: 46066
A26: =DAYS360(I26,$B$1) -> 148 | B26: =DAYS360($B$1,P27) -> -45448 | C26: Producto: 2124001702010101 / BISA OLLA CONVEXA 16 A/T | D26: =VLOOKUP(VALUE(MID($C26,13,2)), codigos!$A$2:$B$60, 2, 1) & " " & VLOOKUP(VALUE(MID($C26,15,4)), codigos!$E$2:$F$102, 2, FALSE) -> OLLA CONVEXA 16 | E26: =VLOOKUP(VALUE(MID($C26,19,2)),codigos!$H$2:$I$62,2,1) & " " & VLOOKUP(VALUE(MID($C26,21,2)),codigos!$K$2:$L$12,2,FALSE) -> A/T S/I | F26: MA DE LOS ANGELES | G26: BO | H26: 00000909 | I26: 30/10/2025 | J26: 12 | K26: 12 | L26: =+J26-K26 -> 0 | O26: 46066
A27: =DAYS360(I27,$B$1) -> 148 | B27: =DAYS360($B$1,P28) -> -45448 | C27: Producto: 2124002202010101 / BISA OLLA CONVEXA 20 A/T | D27: =VLOOKUP(VALUE(MID($C27,13,2)), codigos!$A$2:$B$60, 2, 1) & " " & VLOOKUP(VALUE(MID($C27,15,4)), codigos!$E$2:$F$102, 2, FALSE) -> OLLA CONVEXA 20 | E27: =VLOOKUP(VALUE(MID($C27,19,2)),codigos!$H$2:$I$62,2,1) & " " & VLOOKUP(VALUE(MID($C27,21,2)),codigos!$K$2:$L$12,2,FALSE) -> A/T S/I | F27: MA DE LOS ANGELES | G27: BO | H27: 00000909 | I27: 30/10/2025 | J27: 36 | K27: =12+12+12 -> 36 | L27: =+J27-K27 -> 0 | O27: 46066
A28: =DAYS360(I28,$B$1) -> 148 | B28: =DAYS360($B$1,P29) -> -45448 | C28: Producto: 2124002902010101 / BISA OLLA CONVEXA 30 A/T | D28: =VLOOKUP(VALUE(MID($C28,13,2)), codigos!$A$2:$B$60, 2, 1) & " " & VLOOKUP(VALUE(MID($C28,15,4)), codigos!$E$2:$F$102, 2, FALSE) -> OLLA CONVEXA 30 | E28: =VLOOKUP(VALUE(MID($C28,19,2)),codigos!$H$2:$I$62,2,1) & " " & VLOOKUP(VALUE(MID($C28,21,2)),codigos!$K$2:$L$12,2,FALSE) -> A/T S/I | F28: MA DE LOS ANGELES | G28: BO | H28: 00000909 | I28: 30/10/2025 | J28: 20 | K28: =14+6 -> 20 | L28: =+J28-K28 -> 0 | O28: 46066
A29: =DAYS360(I29,$B$1) -> 148 | B29: =DAYS360($B$1,#REF!) -> #REF! | C29: Producto: 2136002402010101 / BISA SARTEN 22 A/T | D29: =VLOOKUP(VALUE(MID($C29,13,2)), codigos!$A$2:$B$60, 2, 1) & " " & VLOOKUP(VALUE(MID($C29,15,4)), codigos!$E$2:$F$102, 2, FALSE) -> SARTEN 22 | E29: =VLOOKUP(VALUE(MID($C29,19,2)),codigos!$H$2:$I$62,2,1) & " " & VLOOKUP(VALUE(MID($C29,21,2)),codigos!$K$2:$L$12,2,FALSE) -> A/T S/I | F29: MA DE LOS ANGELES | G29: BO | H29: 00000909 | I29: 30/10/2025 | J29: 36 | K29: 36 | L29: =+J29-K29 -> 0 | O29: 46066
A30: =DAYS360(I30,$B$1) -> 73 | C30: Producto: 2143006301010101 / BISA VAJILLA LAVANDA 24 PZ | D30: =VLOOKUP(VALUE(MID($C30,13,2)), codigos!$A$2:$B$60, 2, 1) & " " & VLOOKUP(VALUE(MID($C30,15,4)), codigos!$E$2:$F$102, 2, FALSE) -> VAJILLA LAVANDA | E30: =VLOOKUP(VALUE(MID($C30,19,2)),codigos!$H$2:$I$62,2,1) & " " & VLOOKUP(VALUE(MID($C30,21,2)),codigos!$K$2:$L$12,2,FALSE) -> S/I S/I | F30: VENTA AL PUBLICO | G30: ALM | H30: 00000005 | I30: 15/01/2026 | J30: 30 | K30: =1 -> 1 | L30: =+J30-K30 -> 29 | M30: =(SUM(K30:K34))/(SUM(J30:J34)) -> 0.045454545 | O30: 46080
A31: =DAYS360(I31,$B$1) -> 73 | C31: Producto: 2143006401010101 / BISA VAJILLA LE COQ PH | D31: =VLOOKUP(VALUE(MID($C31,13,2)), codigos!$A$2:$B$60, 2, 1) & " " & VLOOKUP(VALUE(MID($C31,15,4)), codigos!$E$2:$F$102, 2, FALSE) -> VAJILLA LE COQ | E31: =VLOOKUP(VALUE(MID($C31,19,2)),codigos!$H$2:$I$62,2,1) & " " & VLOOKUP(VALUE(MID($C31,21,2)),codigos!$K$2:$L$12,2,FALSE) -> S/I S/I | F31: VENTA AL PUBLICO | G31: ALM | H31: 00000005 | I31: 15/01/2026 | J31: 20 | K31: 1 | L31: =+J31-K31 -> 19 | O31: 46080
A32: =DAYS360(I32,$B$1) -> 73 | C32: Producto: 2143006701010101 / BISA VAJILLA MOSCA EN EL PLATO PH | D32: =VLOOKUP(VALUE(MID($C32,13,2)), codigos!$A$2:$B$60, 2, 1) & " " & VLOOKUP(VALUE(MID($C32,15,4)), codigos!$E$2:$F$102, 2, FALSE) -> VAJILLA MOSCA EN EL PLATO | E32: =VLOOKUP(VALUE(MID($C32,19,2)),codigos!$H$2:$I$62,2,1) & " " & VLOOKUP(VALUE(MID($C32,21,2)),codigos!$K$2:$L$12,2,FALSE) -> S/I S/I | F32: VENTA AL PUBLICO | G32: ALM | H32: 00000005 | I32: 15/01/2026 | J32: 20 | K32: 0 | L32: =+J32-K32 -> 20 | O32: 46080
A33: =DAYS360(I33,$B$1) -> 73 | C33: Producto: 2143006901010101 / BISA VAJILLA VELO 24 PZ | D33: =VLOOKUP(VALUE(MID($C33,13,2)), codigos!$A$2:$B$60, 2, 1) & " " & VLOOKUP(VALUE(MID($C33,15,4)), codigos!$E$2:$F$102, 2, FALSE) -> VAJILLA VELO | E33: =VLOOKUP(VALUE(MID($C33,19,2)),codigos!$H$2:$I$62,2,1) & " " & VLOOKUP(VALUE(MID($C33,21,2)),codigos!$K$2:$L$12,2,FALSE) -> S/I S/I | F33: VENTA AL PUBLICO | G33: ALM | H33: 00000005 | I33: 15/01/2026 | J33: 15 | K33: 0 | L33: =+J33-K33 -> 15 | O33: 46080
A34: =DAYS360(I34,$B$1) -> 73 | C34: Producto: 2143007401010101 / BISA VAJILLA CERRADO MARINO C | D34: =VLOOKUP(VALUE(MID($C34,13,2)), codigos!$A$2:$B$60, 2, 1) & " " & VLOOKUP(VALUE(MID($C34,15,4)), codigos!$E$2:$F$102, 2, FALSE) -> VAJILLA CERRADO MARINO | E34: =VLOOKUP(VALUE(MID($C34,19,2)),codigos!$H$2:$I$62,2,1) & " " & VLOOKUP(VALUE(MID($C34,21,2)),codigos!$K$2:$L$12,2,FALSE) -> S/I S/I | F34: VENTA AL PUBLICO | G34: ALM | H34: 00000005 | I34: 15/01/2026 | J34: 25 | K34: =3 -> 3 | L34: =+J34-K34 -> 22 | O34: 46080
A35: =DAYS360(I35,$B$1) -> 113 | C35: Producto: 2106001702010101 / BISA BUDINERA 16 A/T | D35: =VLOOKUP(VALUE(MID($C35,13,2)), codigos!$A$2:$B$60, 2, 1) & " " & VLOOKUP(VALUE(MID($C35,15,4)), codigos!$E$2:$F$102, 2, FALSE) -> BUDINERA 16 | E35: =VLOOKUP(VALUE(MID($C35,19,2)),codigos!$H$2:$I$62,2,1) & " " & VLOOKUP(VALUE(MID($C35,21,2)),codigos!$K$2:$L$12,2,FALSE) -> A/T S/I | F35: JAVIER CEDILLO | G35: BOC | H35: 00000883 | I35: 05/12/2025 | J35: 108 | K35: =47+18+18+25 -> 108 | L35: =+J35-K35 -> 0 | M35: =(SUM(K35:K41))/(SUM(J35:J41)) -> 0.9562212 | O35: 46101
A36: =DAYS360(I36,$B$1) -> 113 | C36: Producto: 2106002202010101 / BISA BUDINERA 20 A/T | D36: =VLOOKUP(VALUE(MID($C36,13,2)), codigos!$A$2:$B$60, 2, 1) & " " & VLOOKUP(VALUE(MID($C36,15,4)), codigos!$E$2:$F$102, 2, FALSE) -> BUDINERA 20 | E36: =VLOOKUP(VALUE(MID($C36,19,2)),codigos!$H$2:$I$62,2,1) & " " & VLOOKUP(VALUE(MID($C36,21,2)),codigos!$K$2:$L$12,2,FALSE) -> A/T S/I | F36: JAVIER CEDILLO | G36: BOC | H36: 00000883 | I36: 05/12/2025 | J36: 72 | K36: 72 | L36: =+J36-K36 -> 0 | O36: 46101
A37: =DAYS360(I37,$B$1) -> 113 | C37: Producto: 2121004401010101 / BISA JUEGO 5+5 | D37: =VLOOKUP(VALUE(MID($C37,13,2)), codigos!$A$2:$B$60, 2, 1) & " " & VLOOKUP(VALUE(MID($C37,15,4)), codigos!$E$2:$F$102, 2, FALSE) -> JUEGO 5+5 | E37: =VLOOKUP(VALUE(MID($C37,19,2)),codigos!$H$2:$I$62,2,1) & " " & VLOOKUP(VALUE(MID($C37,21,2)),codigos!$K$2:$L$12,2,FALSE) -> S/I S/I | F37: JAVIER CEDILLO | G37: BOC | H37: 00000883 | I37: 05/12/2025 | J37: 50 | K37: =50 -> 50 | L37: =+J37-K37 -> 0 | O37: 46101
A38: =DAYS360(I38,$B$1) -> 113 | C38: Producto: 2124001702010101 / BISA OLLA CONVEXA 16 A/T | D38: =VLOOKUP(VALUE(MID($C38,13,2)), codigos!$A$2:$B$60, 2, 1) & " " & VLOOKUP(VALUE(MID($C38,15,4)), codigos!$E$2:$F$102, 2, FALSE) -> OLLA CONVEXA 16 | E38: =VLOOKUP(VALUE(MID($C38,19,2)),codigos!$H$2:$I$62,2,1) & " " & VLOOKUP(VALUE(MID($C38,21,2)),codigos!$K$2:$L$12,2,FALSE) -> A/T S/I | F38: JAVIER CEDILLO | G38: BOC | H38: 00000883 | I38: 05/12/2025 | J38: 60 | K38: 60 | L38: =+J38-K38 -> 0 | O38: 46101
A39: =DAYS360(I39,$B$1) -> 113 | C39: Producto: 2124002202010101 / BISA OLLA CONVEXA 20 A/T | D39: =VLOOKUP(VALUE(MID($C39,13,2)), codigos!$A$2:$B$60, 2, 1) & " " & VLOOKUP(VALUE(MID($C39,15,4)), codigos!$E$2:$F$102, 2, FALSE) -> OLLA CONVEXA 20 | E39: =VLOOKUP(VALUE(MID($C39,19,2)),codigos!$H$2:$I$62,2,1) & " " & VLOOKUP(VALUE(MID($C39,21,2)),codigos!$K$2:$L$12,2,FALSE) -> A/T S/I | F39: JAVIER CEDILLO | G39: BOC | H39: 00000883 | I39: 05/12/2025 | J39: 48 | K39: =24+12+12 -> 48 | L39: =+J39-K39 -> 0 | O39: 46101
A40: =DAYS360(I40,$B$1) -> 113 | C40: Producto: 2136002402010101 / BISA SARTEN 22 A/T | D40: =VLOOKUP(VALUE(MID($C40,13,2)), codigos!$A$2:$B$60, 2, 1) & " " & VLOOKUP(VALUE(MID($C40,15,4)), codigos!$E$2:$F$102, 2, FALSE) -> SARTEN 22 | E40: =VLOOKUP(VALUE(MID($C40,19,2)),codigos!$H$2:$I$62,2,1) & " " & VLOOKUP(VALUE(MID($C40,21,2)),codigos!$K$2:$L$12,2,FALSE) -> A/T S/I | F40: JAVIER CEDILLO | G40: BOC | H40: 00000883 | I40: 05/12/2025 | J40: 36 | K40: =12-7+10+12+9 -> 36 | L40: =+J40-K40 -> 0 | O40: 46101
...

Sheet 2026
A1: FECHA VENTAS | B1: =+TODAY() -> 46109 | C1: DESCRIPCION | D1: PRODUCTO | E1: COLOR | F1: CLIENTE | G1: Serie documento | H1: DOCUMENTO | I1: FECHA CAPTURA | J1: Cantidad | K1: EXISTENTE | L1: PEDIDO FALTANTE | M1: % | N1: FECHA DE ENTREGA | O1: FECHA PRODUCCION
A2: =DAYS360($B$1,I2) -> -244 | B2: =+N2-I2 -> 165 | C2: Producto: 2132001721010101 / BISA PLATO TROQUELADO 16 GRIS | D2: =VLOOKUP(VALUE(MID($C2,13,2)), codigos!$A$2:$B$60, 2, 1) & " " & VLOOKUP(VALUE(MID($C2,15,4)), codigos!$E$2:$F$102, 2, FALSE) -> PLATO TROQUELADO 16 | E2: =VLOOKUP(VALUE(MID($C2,19,2)),codigos!$H$2:$I$62,2,1) & " " & VLOOKUP(VALUE(MID($C2,21,2)),codigos!$K$2:$L$12,2,FALSE) -> GRIS S/I | F2: QUIEN TIENE TIENDA | G2: VT1 | H2: 00003587 | I2: 24/07/2025 | J2: 42 | K2: 42 | L2: =+J2-K2 -> 0 | M2: =(SUM(K2))/(SUM(J2)) -> 1 | N2: 46027
A3: =DAYS360($B$1,I3) -> -82 | B3: =+N3-I3 -> 3 | C3: Producto: 1111001219010101 / BISA CUBETA 8 GALVANIZADO | D3: =VLOOKUP(VALUE(MID($C3,13,2)), codigos!$A$2:$B$60, 2, 1) & " " & VLOOKUP(VALUE(MID($C3,15,4)), codigos!$E$2:$F$102, 2, FALSE) -> CUBETA 8 | E3: =VLOOKUP(VALUE(MID($C3,19,2)),codigos!$H$2:$I$62,2,1) & " " & VLOOKUP(VALUE(MID($C3,21,2)),codigos!$K$2:$L$12,2,FALSE) -> GALVANIZADO S/I | F3: FERRETERO DE ALBA | G3: VT2 | H3: 5061 | I3: 46028 | J3: 16 | K3: 16 | L3: =+J3-K3 -> 0 | M3: =(SUM(K3))/(SUM(J3)) -> 1 | N3: 46031
A4: =DAYS360($B$1,I4) -> -82 | B4: =+N4-I4 -> 3 | C4: Producto: 1103000519010101 / BISA BAÑO 1 GALVANIZADO | D4: =VLOOKUP(VALUE(MID($C4,13,2)), [2]codigos!$A$2:$B$60, 2, 1) & " " & VLOOKUP(VALUE(MID($C4,15,4)), [2]codigos!$E$2:$F$102, 2, FALSE) -> BAÑO 1 | E4: =VLOOKUP(VALUE(MID($C4,19,2)),[2]codigos!$H$2:$I$62,2,1) & " " & VLOOKUP(VALUE(MID($C4,21,2)),[2]codigos!$K$2:$L$12,2,FALSE) -> GALVANIZADO S/I | F4: SURTIDORA DE PLASTICOS DE COLIMA | G4: VT2 | H4: 00005062 | I4: 06/01/2026 | J4: 5 | K4: 5 | L4: =J4-K4 -> 0 | M4: =(SUM(K4:K8))/(SUM(J4:J8)) -> 0.72222222 | N4: 46031
A5: =DAYS360($B$1,I5) -> -82 | B5: =+N5-I5 -> 3 | C5: Producto: 1103000619010101 / BISA BAÑO 2 GALVANIZADO | D5: =VLOOKUP(VALUE(MID($C5,13,2)), [2]codigos!$A$2:$B$60, 2, 1) & " " & VLOOKUP(VALUE(MID($C5,15,4)), [2]codigos!$E$2:$F$102, 2, FALSE) -> BAÑO 2 | E5: =VLOOKUP(VALUE(MID($C5,19,2)),[2]codigos!$H$2:$I$62,2,1) & " " & VLOOKUP(VALUE(MID($C5,21,2)),[2]codigos!$K$2:$L$12,2,FALSE) -> GALVANIZADO S/I | F5: SURTIDORA DE PLASTICOS DE COLIMA | G5: VT2 | H5: 00005062 | I5: 06/01/2026 | J5: 5 | K5: 5 | L5: =J5-K5 -> 0 | N5: 46031
A6: =DAYS360($B$1,I6) -> -82 | B6: =+N6-I6 -> 3 | C6: Producto: 1103000819010101 / BISA BAÑO 4 GALVANIZADO | D6: =VLOOKUP(VALUE(MID($C6,13,2)), [2]codigos!$A$2:$B$60, 2, 1) & " " & VLOOKUP(VALUE(MID($C6,15,4)), [2]codigos!$E$2:$F$102, 2, FALSE) -> BAÑO 4 | E6: =VLOOKUP(VALUE(MID($C6,19,2)),[2]codigos!$H$2:$I$62,2,1) & " " & VLOOKUP(VALUE(MID($C6,21,2)),[2]codigos!$K$2:$L$12,2,FALSE) -> GALVANIZADO S/I | F6: SURTIDORA DE PLASTICOS DE COLIMA | G6: VT2 | H6: 00005062 | I6: 06/01/2026 | J6: 5 | K6: 0 | L6: =J6-K6 -> 5 | N6: 46031
A7: =DAYS360($B$1,I7) -> -82 | B7: =+N7-I7 -> 3 | C7: Producto: 1103001219010101 / BISA BAÑO 8 GALVANIZADO | D7: =VLOOKUP(VALUE(MID($C7,13,2)), [2]codigos!$A$2:$B$60, 2, 1) & " " & VLOOKUP(VALUE(MID($C7,15,4)), [2]codigos!$E$2:$F$102, 2, FALSE) -> BAÑO 8 | E7: =VLOOKUP(VALUE(MID($C7,19,2)),[2]codigos!$H$2:$I$62,2,1) & " " & VLOOKUP(VALUE(MID($C7,21,2)),[2]codigos!$K$2:$L$12,2,FALSE) -> GALVANIZADO S/I | F7: SURTIDORA DE PLASTICOS DE COLIMA | G7: VT2 | H7: 00005062 | I7: 06/01/2026 | K7: 0 | L7: =J7-K7 -> 0 | N7: 46031
A8: =DAYS360($B$1,I8) -> -82 | B8: =+N8-I8 -> 3 | C8: Producto: 1103001319010101 / BISA BAÑO 10 GALVANIZADO | D8: =VLOOKUP(VALUE(MID($C8,13,2)), [2]codigos!$A$2:$B$60, 2, 1) & " " & VLOOKUP(VALUE(MID($C8,15,4)), [2]codigos!$E$2:$F$102, 2, FALSE) -> BAÑO 10 | E8: =VLOOKUP(VALUE(MID($C8,19,2)),[2]codigos!$H$2:$I$62,2,1) & " " & VLOOKUP(VALUE(MID($C8,21,2)),[2]codigos!$K$2:$L$12,2,FALSE) -> GALVANIZADO S/I | F8: SURTIDORA DE PLASTICOS DE COLIMA | G8: VT2 | H8: 00005062 | I8: 06/01/2026 | J8: 3 | K8: 3 | L8: =J8-K8 -> 0 | N8: 46031
A9: =DAYS360($B$1,I9) -> -82 | B9: =+N9-I9 -> 3 | C9: Producto: 1103001419010101 / BISA BAÑO 12 GALVANIZADO | D9: =VLOOKUP(VALUE(MID($C9,13,2)), [2]codigos!$A$2:$B$60, 2, 1) & " " & VLOOKUP(VALUE(MID($C9,15,4)), [2]codigos!$E$2:$F$102, 2, FALSE) -> BAÑO 12 | E9: =VLOOKUP(VALUE(MID($C9,19,2)),[2]codigos!$H$2:$I$62,2,1) & " " & VLOOKUP(VALUE(MID($C9,21,2)),[2]codigos!$K$2:$L$12,2,FALSE) -> GALVANIZADO S/I | F9: SURTIDORA DE PLASTICOS DE COLIMA | G9: VT2 | H9: 00005062 | I9: 06/01/2026 | J9: 21 | K9: =16+5 -> 21 | L9: =J9-K9 -> 0 | N9: 46031
A10: =DAYS360($B$1,I10) -> -244 | B10: =+N10-I10 -> 176 | C10: Producto: 1103000619010101 / BISA BAÑO 2 GALVANIZADO | D10: =VLOOKUP(VALUE(MID($C10,13,2)), codigos!$A$2:$B$60, 2, 1) & " " & VLOOKUP(VALUE(MID($C10,15,4)), codigos!$E$2:$F$102, 2, FALSE) -> BAÑO 2 | E10: =VLOOKUP(VALUE(MID($C10,19,2)),codigos!$H$2:$I$62,2,1) & " " & VLOOKUP(VALUE(MID($C10,21,2)),codigos!$K$2:$L$12,2,FALSE) -> GALVANIZADO S/I | F10: LL USA LLC | G10: VT2 | H10: 00004931 | I10: 24/07/2025 | J10: 10 | K10: 10 | L10: =+J10-K10 -> 0 | N10: 46038
A11: =DAYS360($B$1,I11) -> -244 | B11: =+N11-I11 -> 176 | C11: Producto: 2122000116050101 / BISA MULTIUSOS BLANCO C/F NEGRO | D11: =VLOOKUP(VALUE(MID($C11,13,2)), codigos!$A$2:$B$60, 2, 1) & " " & VLOOKUP(VALUE(MID($C11,15,4)), codigos!$E$2:$F$102, 2, FALSE) -> MULTIUSOS S/I | E11: =VLOOKUP(VALUE(MID($C11,19,2)),codigos!$H$2:$I$62,2,1) & " " & VLOOKUP(VALUE(MID($C11,21,2)),codigos!$K$2:$L$12,2,FALSE) -> BLANCO NEGRO | F11: LL USA LLC | G11: VT2 | H11: 00004931 | I11: 24/07/2025 | J11: 81 | K11: 81 | L11: =+J11-K11 -> 0 | N11: 46038
A12: =DAYS360($B$1,I12) -> -244 | B12: =+N12-I12 -> 176 | C12: Producto: 2126002216050101 / BISA PLATO AVENERO 20 BLANCO C/F NEGRO | D12: =VLOOKUP(VALUE(MID($C12,13,2)), codigos!$A$2:$B$60, 2, 1) & " " & VLOOKUP(VALUE(MID($C12,15,4)), codigos!$E$2:$F$102, 2, FALSE) -> PLATO AVENERO 20 | E12: =VLOOKUP(VALUE(MID($C12,19,2)),codigos!$H$2:$I$62,2,1) & " " & VLOOKUP(VALUE(MID($C12,21,2)),codigos!$K$2:$L$12,2,FALSE) -> BLANCO NEGRO | F12: LL USA LLC | G12: VT2 | H12: 00004931 | I12: 24/07/2025 | J12: 120 | K12: 120 | L12: =+J12-K12 -> 0 | N12: 46038
A13: =DAYS360($B$1,I13) -> -244 | B13: =+N13-I13 -> 176 | C13: Producto: 2128001726010101 / BISA PLATO BISTRO 16 NEGRO | D13: =VLOOKUP(VALUE(MID($C13,13,2)), codigos!$A$2:$B$60, 2, 1) & " " & VLOOKUP(VALUE(MID($C13,15,4)), codigos!$E$2:$F$102, 2, FALSE) -> PLATO BISTRO 16 | E13: =VLOOKUP(VALUE(MID($C13,19,2)),codigos!$H$2:$I$62,2,1) & " " & VLOOKUP(VALUE(MID($C13,21,2)),codigos!$K$2:$L$12,2,FALSE) -> NEGRO S/I | F13: LL USA LLC | G13: VT2 | H13: 00004931 | I13: 24/07/2025 | J13: 72 | K13: 72 | L13: =+J13-K13 -> 0 | N13: 46038
A14: =DAYS360($B$1,I14) -> -244 | B14: =+N14-I14 -> 176 | C14: Producto: 2129002716050101 / BISA PLATO HONDO 27 BLANCO C/F NEGRO | D14: =VLOOKUP(VALUE(MID($C14,13,2)), codigos!$A$2:$B$60, 2, 1) & " " & VLOOKUP(VALUE(MID($C14,15,4)), codigos!$E$2:$F$102, 2, FALSE) -> PLATO HONDO 27 | E14: =VLOOKUP(VALUE(MID($C14,19,2)),codigos!$H$2:$I$62,2,1) & " " & VLOOKUP(VALUE(MID($C14,21,2)),codigos!$K$2:$L$12,2,FALSE) -> BLANCO NEGRO | F14: LL USA LLC | G14: VT2 | H14: 00004931 | I14: 24/07/2025 | J14: 81 | K14: =77+4 -> 81 | L14: =+J14-K14 -> 0 | N14: 46038
A15: =DAYS360($B$1,I15) -> -244 | B15: =+N15-I15 -> 176 | C15: Producto: 2130002216050101 / BISA PLATO LISO 20 BLANCO C/F NEGRO | D15: =VLOOKUP(VALUE(MID($C15,13,2)), codigos!$A$2:$B$60, 2, 1) & " " & VLOOKUP(VALUE(MID($C15,15,4)), codigos!$E$2:$F$102, 2, FALSE) -> PLATO LISO 20 | E15: =VLOOKUP(VALUE(MID($C15,19,2)),codigos!$H$2:$I$62,2,1) & " " & VLOOKUP(VALUE(MID($C15,21,2)),codigos!$K$2:$L$12,2,FALSE) -> BLANCO NEGRO | F15: LL USA LLC | G15: VT2 | H15: 00004931 | I15: 24/07/2025 | J15: 801 | K15: =108+4+120+4+132+384+49 -> 801 | L15: =+J15-K15 -> 0 | N15: 46038
A16: =DAYS360($B$1,I16) -> -244 | B16: =+N16-I16 -> 176 | C16: Producto: 2139001216050101 / BISA TAZON 8 BLANCO C/F NEGRO | D16: =VLOOKUP(VALUE(MID($C16,13,2)), codigos!$A$2:$B$60, 2, 1) & " " & VLOOKUP(VALUE(MID($C16,15,4)), codigos!$E$2:$F$102, 2, FALSE) -> TAZON 8 | E16: =VLOOKUP(VALUE(MID($C16,19,2)),codigos!$H$2:$I$62,2,1) & " " & VLOOKUP(VALUE(MID($C16,21,2)),codigos!$K$2:$L$12,2,FALSE) -> BLANCO NEGRO | F16: LL USA LLC | G16: VT2 | H16: 00004931 | I16: 24/07/2025 | J16: 882 | K16: =468+414 -> 882 | L16: =+J16-K16 -> 0 | N16: 46038
A17: =DAYS360($B$1,I17) -> -244 | B17: =+N17-I17 -> 176 | C17: Producto: 2139002212010101 / BISA TAZON 20 BICOLOR NARANJA | D17: =VLOOKUP(VALUE(MID($C17,13,2)), codigos!$A$2:$B$60, 2, 1) & " " & VLOOKUP(VALUE(MID($C17,15,4)), codigos!$E$2:$F$102, 2, FALSE) -> TAZON 20 | E17: =VLOOKUP(VALUE(MID($C17,19,2)),codigos!$H$2:$I$62,2,1) & " " & VLOOKUP(VALUE(MID($C17,21,2)),codigos!$K$2:$L$12,2,FALSE) -> BICOLOR NARANJA S/I | F17: LL USA LLC | G17: VT2 | H17: 00004931 | I17: 24/07/2025 | J17: 150 | K17: =48+42+3+30+27 -> 150 | L17: =+J17-K17 -> 0 | N17: 46038
A18: =DAYS360($B$1,I18) -> -244 | B18: =+N18-I18 -> 176 | C18: Producto: 2140001216050101 / BISA TAZON INCLINADO 8 BLANCO C/F NEGRO | D18: =VLOOKUP(VALUE(MID($C18,13,2)), codigos!$A$2:$B$60, 2, 1) & " " & VLOOKUP(VALUE(MID($C18,15,4)), codigos!$E$2:$F$102, 2, FALSE) -> TAZON INCLINADO 8 | E18: =VLOOKUP(VALUE(MID($C18,19,2)),codigos!$H$2:$I$62,2,1) & " " & VLOOKUP(VALUE(MID($C18,21,2)),codigos!$K$2:$L$12,2,FALSE) -> BLANCO NEGRO | F18: LL USA LLC | G18: VT2 | H18: 00004931 | I18: 24/07/2025 | J18: 135 | K18: 135 | L18: =+J18-K18 -> 0 | N18: 46038
A19: =DAYS360($B$1,I19) -> -244 | B19: =+N19-I19 -> 176 | C19: Producto: 2130002216050701 / BISA PLATO LISO 20 BLANCO C/F NEGRO DECORADO | D19: =VLOOKUP(VALUE(MID($C19,13,2)), codigos!$A$2:$B$60, 2, 1) & " " & VLOOKUP(VALUE(MID($C19,15,4)), codigos!$E$2:$F$102, 2, FALSE) -> PLATO LISO 20 | E19: =VLOOKUP(VALUE(MID($C19,19,2)),codigos!$H$2:$I$62,2,1) & " " & VLOOKUP(VALUE(MID($C19,21,2)),codigos!$K$2:$L$12,2,FALSE) -> BLANCO NEGRO | F19: LL USA LLC | G19: VT2 | H19: 00004931 | I19: 24/07/2025 | J19: 126 | K19: 126 | L19: =+J19-K19 -> 0 | N19: 46038
A20: =DAYS360($B$1,I20) -> -244 | B20: =+N20-I20 -> 176 | C20: Producto: 2330003020010101 / SANSON PLATO LISO 32 GENERICO | D20: =VLOOKUP(VALUE(MID($C20,13,2)), codigos!$A$2:$B$60, 2, 1) & " " & VLOOKUP(VALUE(MID($C20,15,4)), codigos!$E$2:$F$102, 2, FALSE) -> PLATO LISO 32 | E20: =VLOOKUP(VALUE(MID($C20,19,2)),codigos!$H$2:$I$62,2,1) & " " & VLOOKUP(VALUE(MID($C20,21,2)),codigos!$K$2:$L$12,2,FALSE) -> GENERICO S/I | F20: LL USA LLC | G20: VT2 | H20: 00004931 | I20: 24/07/2025 | J20: 75 | K20: 75 | L20: =+J20-K20 -> 0 | N20: 46038
A21: =DAYS360($B$1,I21) -> -244 | B21: =+N21-I21 -> 176 | C21: Producto: 2133000926010701 / BISA POCILLO 5 NEGRO DECORADO | D21: =VLOOKUP(VALUE(MID($C21,13,2)), codigos!$A$2:$B$60, 2, 1) & " " & VLOOKUP(VALUE(MID($C21,15,4)), codigos!$E$2:$F$102, 2, FALSE) -> POCILLO 5 | E21: =VLOOKUP(VALUE(MID($C21,19,2)),codigos!$H$2:$I$62,2,1) & " " & VLOOKUP(VALUE(MID($C21,21,2)),codigos!$K$2:$L$12,2,FALSE) -> NEGRO S/I | F21: LL USA LLC | G21: VT2 | H21: 00004931 | I21: 24/07/2025 | J21: 72 | K21: 72 | L21: =+J21-K21 -> 0 | N21: 46038
A22: =DAYS360($B$1,I22) -> -244 | B22: =+N22-I22 -> 176 | C22: Producto: 2140002412050101 / BISA TAZON INCLINADO 22 BICOLOR NARANJA | D22: =VLOOKUP(VALUE(MID($C22,13,2)), codigos!$A$2:$B$60, 2, 1) & " " & VLOOKUP(VALUE(MID($C22,15,4)), codigos!$E$2:$F$102, 2, FALSE) -> TAZON INCLINADO 22 | E22: =VLOOKUP(VALUE(MID($C22,19,2)),codigos!$H$2:$I$62,2,1) & " " & VLOOKUP(VALUE(MID($C22,21,2)),codigos!$K$2:$L$12,2,FALSE) -> BICOLOR NARANJA NEGRO | F22: LL USA LLC | G22: VT2 | H22: 00004931 | I22: 24/07/2025 | J22: 126 | K22: =60+2+24+40 -> 126 | L22: =+J22-K22 -> 0 | N22: 46038
A23: =DAYS360($B$1,I23) -> -244 | B23: =+N23-I23 -> 176 | C23: Producto: 2133000912050101 / BISA POCILLO 5 BICOLOR NARANJA | D23: =VLOOKUP(VALUE(MID($C23,13,2)), codigos!$A$2:$B$60, 2, 1) & " " & VLOOKUP(VALUE(MID($C23,15,4)), codigos!$E$2:$F$102, 2, FALSE) -> POCILLO 5 | E23: =VLOOKUP(VALUE(MID($C23,19,2)),codigos!$H$2:$I$62,2,1) & " " & VLOOKUP(VALUE(MID($C23,21,2)),codigos!$K$2:$L$12,2,FALSE) -> BICOLOR NARANJA NEGRO | F23: LL USA LLC | G23: VT2 | H23: 00004931 | I23: 24/07/2025 | J23: 750 | K23: =456+96+198 -> 750 | L23: =+J23-K23 -> 0 | N23: 46038
A24: =DAYS360($B$1,I24) -> -244 | B24: =+N24-I24 -> 176 | C24: Producto: 2138000126010701 / BISA TAZA BISTRO NEGRO DECORADO | D24: =VLOOKUP(VALUE(MID($C24,13,2)), codigos!$A$2:$B$60, 2, 1) & " " & VLOOKUP(VALUE(MID($C24,15,4)), codigos!$E$2:$F$102, 2, FALSE) -> TAZA BISTRO S/I | E24: =VLOOKUP(VALUE(MID($C24,19,2)),codigos!$H$2:$I$62,2,1) & " " & VLOOKUP(VALUE(MID($C24,21,2)),codigos!$K$2:$L$12,2,FALSE) -> NEGRO S/I | F24: LL USA LLC | G24: VT2 | H24: 00004931 | I24: 24/07/2025 | J24: 63 | K24: 63 | L24: =+J24-K24 -> 0 | N24: 46038
A25: =DAYS360($B$1,I25) -> -244 | B25: =+N25-I25 -> 176 | C25: Producto: 2145001227010701 / BISA VASO 8 NEGRO MOTAS DECPRADO | D25: =VLOOKUP(VALUE(MID($C25,13,2)), codigos!$A$2:$B$60, 2, 1) & " " & VLOOKUP(VALUE(MID($C25,15,4)), codigos!$E$2:$F$102, 2, FALSE) -> VASO 8 | E25: =VLOOKUP(VALUE(MID($C25,19,2)),codigos!$H$2:$I$62,2,1) & " " & VLOOKUP(VALUE(MID($C25,21,2)),codigos!$K$2:$L$12,2,FALSE) -> NEGRO MOTAS S/I | F25: LL USA LLC | G25: VT2 | H25: 00004931 | I25: 24/07/2025 | J25: 72 | K25: 72 | L25: =+J25-K25 -> 0 | N25: 46038
A26: =DAYS360($B$1,I26) -> -244 | B26: =+N26-I26 -> 176 | C26: Producto: 2130001727010701 / BISA PLATO LISO 16 NEGRO MOTAS DECORADO | D26: =VLOOKUP(VALUE(MID($C26,13,2)), codigos!$A$2:$B$60, 2, 1) & " " & VLOOKUP(VALUE(MID($C26,15,4)), codigos!$E$2:$F$102, 2, FALSE) -> PLATO LISO 16 | E26: =VLOOKUP(VALUE(MID($C26,19,2)),codigos!$H$2:$I$62,2,1) & " " & VLOOKUP(VALUE(MID($C26,21,2)),codigos!$K$2:$L$12,2,FALSE) -> NEGRO MOTAS S/I | F26: LL USA LLC | G26: VT2 | H26: 00004931 | I26: 24/07/2025 | J26: 63 | K26: 63 | L26: =+J26-K26 -> 0 | M26: =(SUM(K10:K26))/(SUM(J10:J26)) -> 1 | N26: 46038
A27: =DAYS360($B$1,I27) -> -244 | B27: =+N27-I27 -> 176 | C27: Producto: 1103000619010101 / BISA BAÑO 2 GALVANIZADO | D27: =VLOOKUP(VALUE(MID($C27,13,2)), codigos!$A$2:$B$60, 2, 1) & " " & VLOOKUP(VALUE(MID($C27,15,4)), codigos!$E$2:$F$102, 2, FALSE) -> BAÑO 2 | E27: =VLOOKUP(VALUE(MID($C27,19,2)),codigos!$H$2:$I$62,2,1) & " " & VLOOKUP(VALUE(MID($C27,21,2)),codigos!$K$2:$L$12,2,FALSE) -> GALVANIZADO S/I | F27: LL SL | G27: VT2 | H27: 00004928 | I27: 24/07/2025 | J27: 10 | K27: 10 | L27: =+J27-K27 -> 0 | N27: 46038
A28: =DAYS360($B$1,I28) -> -244 | B28: =+N28-I28 -> 176 | C28: Producto: 2122000116050101 / BISA MULTIUSOS BLANCO C/F NEGRO | D28: =VLOOKUP(VALUE(MID($C28,13,2)), codigos!$A$2:$B$60, 2, 1) & " " & VLOOKUP(VALUE(MID($C28,15,4)), codigos!$E$2:$F$102, 2, FALSE) -> MULTIUSOS S/I | E28: =VLOOKUP(VALUE(MID($C28,19,2)),codigos!$H$2:$I$62,2,1) & " " & VLOOKUP(VALUE(MID($C28,21,2)),codigos!$K$2:$L$12,2,FALSE) -> BLANCO NEGRO | F28: LL SL | G28: VT2 | H28: 00004928 | I28: 24/07/2025 | J28: 81 | K28: 81 | L28: =+J28-K28 -> 0 | N28: 46038
A29: =DAYS360($B$1,I29) -> -244 | B29: =+N29-I29 -> 176 | C29: Producto: 2126002216050101 / BISA PLATO AVENERO 20 BLANCO C/F NEGRO | D29: =VLOOKUP(VALUE(MID($C29,13,2)), codigos!$A$2:$B$60, 2, 1) & " " & VLOOKUP(VALUE(MID($C29,15,4)), codigos!$E$2:$F$102, 2, FALSE) -> PLATO AVENERO 20 | E29: =VLOOKUP(VALUE(MID($C29,19,2)),codigos!$H$2:$I$62,2,1) & " " & VLOOKUP(VALUE(MID($C29,21,2)),codigos!$K$2:$L$12,2,FALSE) -> BLANCO NEGRO | F29: LL SL | G29: VT2 | H29: 00004928 | I29: 24/07/2025 | J29: 120 | K29: 120 | L29: =+J29-K29 -> 0 | N29: 46038
A30: =DAYS360($B$1,I30) -> -244 | B30: =+N30-I30 -> 176 | C30: Producto: 2128001726010101 / BISA PLATO BISTRO 16 NEGRO | D30: =VLOOKUP(VALUE(MID($C30,13,2)), codigos!$A$2:$B$60, 2, 1) & " " & VLOOKUP(VALUE(MID($C30,15,4)), codigos!$E$2:$F$102, 2, FALSE) -> PLATO BISTRO 16 | E30: =VLOOKUP(VALUE(MID($C30,19,2)),codigos!$H$2:$I$62,2,1) & " " & VLOOKUP(VALUE(MID($C30,21,2)),codigos!$K$2:$L$12,2,FALSE) -> NEGRO S/I | F30: LL SL | G30: VT2 | H30: 00004928 | I30: 24/07/2025 | J30: 72 | K30: 72 | L30: =+J30-K30 -> 0 | N30: 46038
A31: =DAYS360($B$1,I31) -> -244 | B31: =+N31-I31 -> 176 | C31: Producto: 2129002716050101 / BISA PLATO HONDO 27 BLANCO C/F NEGRO | D31: =VLOOKUP(VALUE(MID($C31,13,2)), codigos!$A$2:$B$60, 2, 1) & " " & VLOOKUP(VALUE(MID($C31,15,4)), codigos!$E$2:$F$102, 2, FALSE) -> PLATO HONDO 27 | E31: =VLOOKUP(VALUE(MID($C31,19,2)),codigos!$H$2:$I$62,2,1) & " " & VLOOKUP(VALUE(MID($C31,21,2)),codigos!$K$2:$L$12,2,FALSE) -> BLANCO NEGRO | F31: LL SL | G31: VT2 | H31: 00004928 | I31: 24/07/2025 | J31: 81 | K31: =14+67 -> 81 | L31: =+J31-K31 -> 0 | N31: 46038
A32: =DAYS360($B$1,I32) -> -244 | B32: =+N32-I32 -> 176 | C32: Producto: 2130002216050701 / BISA PLATO LISO 20 BLANCO C/F NEGRO DECORADO | D32: =VLOOKUP(VALUE(MID($C32,13,2)), codigos!$A$2:$B$60, 2, 1) & " " & VLOOKUP(VALUE(MID($C32,15,4)), codigos!$E$2:$F$102, 2, FALSE) -> PLATO LISO 20 | E32: =VLOOKUP(VALUE(MID($C32,19,2)),codigos!$H$2:$I$62,2,1) & " " & VLOOKUP(VALUE(MID($C32,21,2)),codigos!$K$2:$L$12,2,FALSE) -> BLANCO NEGRO | F32: LL SL | G32: VT2 | H32: 00004928 | I32: 24/07/2025 | J32: 126 | K32: 126 | L32: =+J32-K32 -> 0 | N32: 46038
A33: =DAYS360($B$1,I33) -> -244 | B33: =+N33-I33 -> 176 | C33: Producto: 2130002216050101 / BISA PLATO LISO 20 BLANCO C/F NEGRO | D33: =VLOOKUP(VALUE(MID($C33,13,2)), codigos!$A$2:$B$60, 2, 1) & " " & VLOOKUP(VALUE(MID($C33,15,4)), codigos!$E$2:$F$102, 2, FALSE) -> PLATO LISO 20 | E33: =VLOOKUP(VALUE(MID($C33,19,2)),codigos!$H$2:$I$62,2,1) & " " & VLOOKUP(VALUE(MID($C33,21,2)),codigos!$K$2:$L$12,2,FALSE) -> BLANCO NEGRO | F33: LL SL | G33: VT2 | H33: 00004928 | I33: 24/07/2025 | J33: 801 | K33: =599+126+36-24+12+18+34 -> 801 | L33: =+J33-K33 -> 0 | N33: 46038
